Workbook

Sheet Análisis de informes
A1: INFORME | B1: Tabla HANA | C1: Tabla ORACLE | D1: Incluír en CREAR_TABLAS | E1: Comentario
A2: 1.11 Percepción Agentes | B2: OUT_PERC_AGENTES_FILE | C2: =IF(ISBLANK(B2),"",VLOOKUP(B2,'EQ TABLAS'!D:E,2,FALSE)) -> INYC_PERC_AGENTES | D2: =IF(C2="","",IF(COUNTIF('Tablas CREAR_TABLAS'!A:A,C2)>0,"SI","NO")) -> SI
A3: 1.11 Percepción Agentes | B3: OUT_JERARQUIA_REP | C3: =IF(ISBLANK(B3),"",VLOOKUP(B3,'EQ TABLAS'!D:E,2,FALSE)) -> INYC_JERARQUIA | D3: =IF(C3="","",IF(COUNTIF('Tablas CREAR_TABLAS'!A:A,C3)>0,"SI","NO")) -> SI
A4: 1.11 Percepción Agentes | B4: OUT_FECHAS_WEBI_REP | C4: =IF(ISBLANK(B4),"",VLOOKUP(B4,'EQ TABLAS'!D:E,2,FALSE)) -> INYC_FECHAS_WEBI | D4: =IF(C4="","",IF(COUNTIF('Tablas CREAR_TABLAS'!A:A,C4)>0,"SI","NO")) -> SI
A5: 1.12 Producción Agentes | B5: OUT_JERARQUIA_REP | C5: =IF(ISBLANK(B5),"",VLOOKUP(B5,'EQ TABLAS'!D:E,2,FALSE)) -> INYC_JERARQUIA | D5: =IF(C5="","",IF(COUNTIF('Tablas CREAR_TABLAS'!A:A,C5)>0,"SI","NO")) -> SI
A6: 1.12 Producción Agentes | B6: OUT_PROD_AGENTES_REP | C6: =IF(ISBLANK(B6),"",VLOOKUP(B6,'EQ TABLAS'!D:E,2,FALSE)) -> INYC_PROD_AGENTES | D6: =IF(C6="","",IF(COUNTIF('Tablas CREAR_TABLAS'!A:A,C6)>0,"SI","NO")) -> SI
A7: 1.13 Percepción Inspectores | B7: OUT_PERC_INSPECTORES_FILE | C7: =IF(ISBLANK(B7),"",VLOOKUP(B7,'EQ TABLAS'!D:E,2,FALSE)) -> INYC_PERC_INSPECTORES | D7: =IF(C7="","",IF(COUNTIF('Tablas CREAR_TABLAS'!A:A,C7)>0,"SI","NO")) -> SI
A8: 1.13 Percepción Inspectores | B8: OUT_JERARQUIA_REP | C8: =IF(ISBLANK(B8),"",VLOOKUP(B8,'EQ TABLAS'!D:E,2,FALSE)) -> INYC_JERARQUIA | D8: =IF(C8="","",IF(COUNTIF('Tablas CREAR_TABLAS'!A:A,C8)>0,"SI","NO")) -> SI
A9: 1.13 Percepción Inspectores | B9: OUT_FECHAS_WEBI_REP | C9: =IF(ISBLANK(B9),"",VLOOKUP(B9,'EQ TABLAS'!D:E,2,FALSE)) -> INYC_FECHAS_WEBI | D9: =IF(C9="","",IF(COUNTIF('Tablas CREAR_TABLAS'!A:A,C9)>0,"SI","NO")) -> SI
A10: 1.14 Producción Inspectores | B10: OUT_JERARQUIA_REP | C10: =IF(ISBLANK(B10),"",VLOOKUP(B10,'EQ TABLAS'!D:E,2,FALSE)) -> INYC_JERARQUIA | D10: =IF(C10="","",IF(COUNTIF('Tablas CREAR_TABLAS'!A:A,C10)>0,"SI","NO")) -> SI
A11: 1.14 Producción Inspectores | B11: OUT_PROD_INSPECTORES_REP | C11: =IF(ISBLANK(B11),"",VLOOKUP(B11,'EQ TABLAS'!D:E,2,FALSE)) -> INYC_PROD_INSPECTORES | D11: =IF(C11="","",IF(COUNTIF('Tablas CREAR_TABLAS'!A:A,C11)>0,"SI","NO")) -> SI
A12: 1.14 Producción Inspectores | B12: OUT_FECHAS_WEBI_REP | C12: =IF(ISBLANK(B12),"",VLOOKUP(B12,'EQ TABLAS'!D:E,2,FALSE)) -> INYC_FECHAS_WEBI | D12: =IF(C12="","",IF(COUNTIF('Tablas CREAR_TABLAS'!A:A,C12)>0,"SI","NO")) -> SI
A13: 1.16 Inspectores Activos | B13: OUT_INSP_ACTIVOS_REP | C13: =IF(ISBLANK(B13),"",VLOOKUP(B13,'EQ TABLAS'!D:E,2,FALSE)) -> INYC_INSP_ACTIVOS | D13: =IF(C13="","",IF(COUNTIF('Tablas CREAR_TABLAS'!A:A,C13)>0,"SI","NO")) -> SI
... A34: S4 Factura | B34: OUT_JERARQUIA_REP | C34: =IF(ISBLANK(B34),"",VLOOKUP(B34,'EQ TABLAS'!D:E,2,FALSE)) -> INYC_JERARQUIA | D34: =IF(C34="","",IF(COUNTIF('Tablas CREAR_TABLAS'!A:A,C34)>0,"SI","NO")) -> SI
A35: S4 Factura | B35: OUT_S4_FACTURA_REP | C35: =IF(ISBLANK(B35),"",VLOOKUP(B35,'EQ TABLAS'!D:E,2,FALSE)) -> INYC_S4_FACTURA | D35: =IF(OR(ISBLANK(C35),C35=""),"",IF(COUNTIF('Tablas CREAR_TABLAS'!A:A,C35)>0,"SI","NO")) -> SI
A36: S4 Factura | B36: OUT_FECHAS_WEBI_REP | C36: =IF(ISBLANK(B36),"",VLOOKUP(B36,'EQ TABLAS'!D:E,2,FALSE)) -> INYC_FECHAS_WEBI | D36: =IF(OR(ISBLANK(C36),C36=""),"",IF(COUNTIF('Tablas CREAR_TABLAS'!A:A,C36)>0,"SI","NO")) -> SI
A37: S4 Factura | B37: FINAL_EXTRACTPAGOS_FILE | C37: =IF(ISBLANK(B37),"",VLOOKUP(B37,'EQ TABLAS'!D:E,2,FALSE)) -> INYC_EXTRACTPAGOS_FINAL | D37: =IF(OR(ISBLANK(C37),C37=""),"",IF(COUNTIF('Tablas CREAR_TABLAS'!A:A,C37)>0,"SI","NO")) -> NO
A38: S4 Factura | B38: OUT_LC_S4_FACTURA_REP | C38: =IF(ISBLANK(B38),"",VLOOKUP(B38,'EQ TABLAS'!D:E,2,FALSE)) -> INYC_LC_S4_FACTURA | D38: =IF(OR(ISBLANK(C38),C38=""),"",IF(COUNTIF('Tablas CREAR_TABLAS'!A:A,C38)>0,"SI","NO")) -> SI
A39: S4 Factura | B39: OUT_S4_E_FACTURA_REP | C39: =IF(ISBLANK(B39),"",VLOOKUP(B39,'EQ TABLAS'!D:E,2,FALSE)) -> INYC_S4_E_FACTURA | D39: =IF(OR(ISBLANK(C39),C39=""),"",IF(COUNTIF('Tablas CREAR_TABLAS'!A:A,C39)>0,"SI","NO")) -> SI
A40: S4 Factura | B40: OUT_LC_S4_E_FACTURA_REP | C40: =IF(ISBLANK(B40),"",VLOOKUP(B40,'EQ TABLAS'!D:E,2,FALSE)) -> INYC_LC_S4_E_FACTURA | D40: =IF(OR(ISBLANK(C40),C40=""),"",IF(COUNTIF('Tablas CREAR_TABLAS'!A:A,C40)>0,"SI","NO")) -> SI
A41: S5 Pólizas | B41: OUT_S5_POLIZAS_REP | C41: =IF(ISBLANK(B41),"",VLOOKUP(B41,'EQ TABLAS'!D:E,2,FALSE)) -> INYC_S5_POLIZAS | D41: =IF(OR(ISBLANK(C41),C41=""),"",IF(COUNTIF('Tablas CREAR_TABLAS'!A:A,C41)>0,"SI","NO")) -> SI
A42: S5 Pólizas | B42: OUT_JERARQUIA_REP | C42: =IF(ISBLANK(B42),"",VLOOKUP(B42,'EQ TABLAS'!D:E,2,FALSE)) -> INYC_JERARQUIA | D42: =IF(OR(ISBLANK(C42),C42=""),"",IF(COUNTIF('Tablas CREAR_TABLAS'!A:A,C42)>0,"SI","NO")) -> SI
A43: S5 Pólizas | B43: OUT_FECHAS_WEBI_REP | C43: =IF(ISBLANK(B43),"",VLOOKUP(B43,'EQ TABLAS'!D:E,2,FALSE)) -> INYC_FECHAS_WEBI | D43: =IF(OR(ISBLANK(C43),C43=""),"",IF(COUNTIF('Tablas CREAR_TABLAS'!A:A,C43)>0,"SI","NO")) -> SI
A44: S5 Pólizas | B44: OUT_BAL_S5_POLIZAS_REP | C44: =IF(ISBLANK(B44),"",VLOOKUP(B44,'EQ TABLAS'!D:E,2,FALSE)) -> INYC_BAL_S5_POLIZAS | D44: =IF(OR(ISBLANK(C44),C44=""),"",IF(COUNTIF('Tablas CREAR_TABLAS'!A:A,C44)>0,"SI","NO")) -> SI
A45: S5 Pólizas | B45: OUT_LC_S5_POLIZAS_REP | C45: =IF(ISBLANK(B45),"",VLOOKUP(B45,'EQ TABLAS'!D:E,2,FALSE)) -> INYC_LC_S5_POLIZAS | D45: =IF(OR(ISBLANK(C45),C45=""),"",IF(COUNTIF('Tablas CREAR_TABLAS'!A:A,C45)>0,"SI","NO")) -> SI
A46: S5 Factura | B46: OUT_JERARQUIA_REP | C46: =IF(ISBLANK(B46),"",VLOOKUP(B46,'EQ TABLAS'!D:E,2,FALSE)) -> INYC_JERARQUIA | D46: =IF(OR(ISBLANK(C46),C46=""),"",IF(COUNTIF('Tablas CREAR_TABLAS'!A:A,C46)>0,"SI","NO")) -> SI
... A50: S5 Factura | B50: OUT_LC_S5_FACTURA_REP | C50: =IF(ISBLANK(B50),"",VLOOKUP(B50,'EQ TABLAS'!D:E,2,FALSE)) -> INYC_LC_S5_FACTURA | D50: =IF(OR(ISBLANK(C50),C50=""),"",IF(COUNTIF('Tablas CREAR_TABLAS'!A:A,C50)>0,"SI","NO")) -> SI
C51: =IF(ISBLANK(B51),"",VLOOKUP(B51,'EQ TABLAS'!D:E,2,FALSE)) | D51: =IF(OR(ISBLANK(C51),C51=""),"",IF(COUNTIF('Tablas CREAR_TABLAS'!A:A,C51)>0,"SI","NO"))

Sheet Tablas únicas
A1: Counter | B1: Informe | C1: Tabla ORACLE
A2: =ROW()-1 -> 1 | B2: Varios | C2: INYC_JERARQUIA
A3: =ROW()-1 -> 2 | B3: Varios | C3: INYC_FECHAS_WEBI
A4: =ROW()-1 -> 3 | B4: 1.11 Percepción Agentes | C4: INYC_PERC_AGENTES
A5: =ROW()-1 -> 4 | B5: 1.12 Producción Agentes | C5: INYC_PROD_AGENTES
A6: =ROW()-1 -> 5 | B6: 1.13 Percepción Inspectores | C6: INYC_PERC_INSPECTORES
A7: =ROW()-1 -> 6 | B7: 1.14 Producción Inspectores | C7: INYC_PROD_INSPECTORES
A8: =ROW()-1 -> 7 | B8: 1.16 Inspectores Activos | C8: INYC_INSP_ACTIVOS
A9: =ROW()-1 -> 8 | B9: 1.26 Rappel Producción Agentes | C9: INYC_RPA_RESUMEN
A10: =ROW()-1 -> 9 | B10: 1.26 Rappel Producción Agentes | C10: INYC_LC_RPA_RESUMEN
A11: =ROW()-1 -> 10 | B11: 1.26 Rappel Producción Agentes | C11: INYC_BAL_RPA_RESUMEN
A12: =ROW()-1 -> 11 | B12: 1.26 Rappel Producción Agentes | C12: INYC_ASI_RESUMEN
A13: =ROW()-1 -> 12 | B13: 1.26 Rappel Producción Agentes | C13: INYC_LC_ASI_RESUMEN
... A29: =ROW()-1 -> 28 | B29: S5 Factura | C29: INYC_LC_S5_FACTURA

Sheet Tablas CREAR_TABLAS
A1: TABLAS | B1: INFORMES
A2: INYC_FECHAS_WEBI | B2: =VLOOKUP('Tablas CREAR_TABLAS'!A2,'EQ TABLAS'!A:B,2,FALSE) -> OUT_FECHAS_WEBI_REP
A3: INYC_USUARIOS_TEMP | B3: =VLOOKUP('Tablas CREAR_TABLAS'!A3,'EQ TABLAS'!A:B,2,FALSE) -> OUT_USUARIOS_REP
A4: INYC_TABLA_IRPF | B4: =VLOOKUP('Tablas CREAR_TABLAS'!A4,'EQ TABLAS'!A:B,2,FALSE) -> TEMP_TABLA_IRPF_REP
A5: INYC_TABLA_PERCEPCIONES | B5: =VLOOKUP('Tablas CREAR_TABLAS'!A5,'EQ TABLAS'!A:B,2,FALSE) -> TEMP_PERCEPCIONES_REP
A6: INYC_TXN_MES_TEMP | B6: =VLOOKUP('Tablas CREAR_TABLAS'!A6,'EQ TABLAS'!A:B,2,FALSE) -> TEMP_TXN_MES_REP
A7: INYC_CREDITOS_MES_TEMP | B7: =VLOOKUP('Tablas CREAR_TABLAS'!A7,'EQ TABLAS'!A:B,2,FALSE) -> TEMP_CREDITOS_MES_REP
A8: INYC_MEDIDAS_MES_TEMP | B8: =VLOOKUP('Tablas CREAR_TABLAS'!A8,'EQ TABLAS'!A:B,2,FALSE) -> TEMP_MEDIDAS_MES_REP
A9: INYC_PAGOS_MES_TEMP | B9: =VLOOKUP('Tablas CREAR_TABLAS'!A9,'EQ TABLAS'!A:B,2,FALSE) -> TEMP_PAGOS_MES_REP
A10: INYC_OFICINAS_MES_TEMP | B10: =VLOOKUP('Tablas CREAR_TABLAS'!A10,'EQ TABLAS'!A:B,2,FALSE) -> TEMP_OFICINAS_MES_REP
A11: INYC_AGENTES_MES_TEMP | B11: =VLOOKUP('Tablas CREAR_TABLAS'!A11,'EQ TABLAS'!A:B,2,FALSE) -> TEMP_AGENTES_MES_REP
A12: INYC_AGENTES_PRIN_MES_TEMP | B12: =VLOOKUP('Tablas CREAR_TABLAS'!A12,'EQ TABLAS'!A:B,2,FALSE) -> TEMP_AGENTES_PRIN_MES_REP
A13: INYC_JERARQUIA | B13: =VLOOKUP('Tablas CREAR_TABLAS'!A13,'EQ TABLAS'!A:B,2,FALSE) -> OUT_JERARQUIA_REP
... A207: INYC_LC_GES_DETALLE | B207: =VLOOKUP('Tablas CREAR_TABLAS'!A207,'EQ TABLAS'!A:B,2,FALSE) -> OUT_LC_GES_DETALLE_REP

Sheet EQ TABLAS
A1: TABLE_NAME | B1: NOMBRE SAP HANA | D1: NOMBRE SAP HANA | E1: TABLE_NAME
A2: INYC_AUTOLIQUIDACION_FINAL | B2: FINAL_AUTOLIQUIDACION_FILE | D2: FINAL_AUTOLIQUIDACION_FILE | E2: INYC_AUTOLIQUIDACION_FINAL
A3: INYC_AUTOLIQUIDACION_INFORME | B3: OUT_AUTOLIQUIDACION_INFORME_FILE | D3: OUT_AUTOLIQUIDACION_INFORME_FILE | E3: INYC_AUTOLIQUIDACION_INFORME
A4: INYC_BAL_S4_E_POLIZAS | B4: OUT_BAL_S4_E_POLIZAS_REP | D4: OUT_BAL_S4_E_POLIZAS_REP | E4: INYC_BAL_S4_E_POLIZAS
A5: INYC_BAL_S4_POLIZAS | B5: OUT_BAL_S4_POLIZAS_REP | D5: OUT_BAL_S4_POLIZAS_REP | E5: INYC_BAL_S4_POLIZAS
A6: INYC_BAL_S5_E_FACTURA | B6: OUT_BAL_S5_E_FACTURA_REP | D6: OUT_BAL_S5_E_FACTURA_REP | E6: INYC_BAL_S5_E_FACTURA
A7: INYC_BAL_S5_E_POLIZAS | B7: OUT_BAL_S5_E_POLIZAS_REP | D7: OUT_BAL_S5_E_POLIZAS_REP | E7: INYC_BAL_S5_E_POLIZAS
A8: INYC_BAL_S5_FACTURA | B8: OUT_BAL_S5_FACTURA_REP | D8: OUT_BAL_S5_FACTURA_REP | E8: INYC_BAL_S5_FACTURA
A9: INYC_BAL_S5_POLIZAS | B9: OUT_BAL_S5_POLIZAS_REP | D9: OUT_BAL_S5_POLIZAS_REP | E9: INYC_BAL_S5_POLIZAS
A10: INYC_CARTERA_LP_DET | B10: CARTERA_DDEE | D10: CARTERA_DDEE | E10: INYC_CARTERA_LP_DET
A11: INYC_CARTERA_LP_DET_NOMEXT | B11: TEMP_CARTERA_DDEE_NOMEXT_FILE | D11: TEMP_CARTERA_DDEE_NOMEXT_FILE | E11: INYC_CARTERA_LP_DET_NOMEXT
A12: INYC_CUNEXT_FINAL | B12: FINAL_CUNEXT_FILE | D12: FINAL_CUNEXT_FILE | E12: INYC_CUNEXT_FINAL
... A29: INYC_LIQEXT_CABECERA_TEMP | B29: TEMP_LIQEXT_CABECERA_FILE | D29: TEMP_LIQEXT_CABECERA_FILE | E29: INYC_LIQEXT_CABECERA_TEMP
A30: BKP_INYCCEDITTEMP | E30: BKP_INYCCEDITTEMP
A31: BKP_INYCCNFINAENES | E31: BKP_INYCCNFINAENES
A32: BKP_INYCCOMEEMPORAL | E32: BKP_INYCCOMEEMPORAL
A33: BKP_INYCCOMEXDERTEMP | E33: BKP_INYCCOMEXDERTEMP
A34: BKP_INYC_CONF_INF_AGENTES | E34: BKP_INYC_CONF_INF_AGENTES
A35: BKP_INYCCONFORME | E35: BKP_INYCCONFORME
A36: BKP_INYCCXTTXNTEMP | E36: BKP_INYCCXTTXNTEMP
A37: BKP_INYCDFRESUMEN | E37: BKP_INYCDFRESUMEN
A38: BKP_INYCFDETALLE | E38: BKP_INYCFDETALLE
A39: BKP_INYCMEXTFINAL | E39: BKP_INYCMEXTFINAL
A40: BKP_INYCPEPARSUMEN | E40: BKP_INYCPEPARSUMEN
A41: BKP_INYCPEPIRESUMEN | E41: BKP_INYCPEPIRESUMEN
... A44: BKP_3202731_INYCJEREXTPARFINAL | E44: BKP_3202731_INYCJEREXTPARFINAL
A45: INYC_AGENTES_MES_TEMP | B45: TEMP_AGENTES_MES_REP | D45: TEMP_AGENTES_MES_REP | E45: INYC_AGENTES_MES_TEMP
A46: INYC_AGENTES_PRIN_MES_TEMP | B46: TEMP_AGENTES_PRIN_MES_REP | D46: TEMP_AGENTES_PRIN_MES_REP | E46: INYC_AGENTES_PRIN_MES_TEMP
A47: INYC_ANCESTOR_MES_TEMP | B47: TEMP_ANCESTOR_MES_REP | D47: TEMP_ANCESTOR_MES_REP | E47: INYC_ANCESTOR_MES_TEMP
A48: INYC_AN_DETALLE | B48: OUT_AN_DETALLE_REP | D48: OUT_AN_DETALLE_REP | E48: INYC_AN_DETALLE
A49: INYC_AN_RESUMEN | B49: OUT_AN_RESUMEN_REP | D49: OUT_AN_RESUMEN_REP | E49: INYC_AN_RESUMEN
A50: INYC_ARBOL_CREDIT_MES_TEMP | E50: INYC_ARBOL_CREDIT_MES_TEMP
A51: INYC_ARBOL_MES_TEMP | E51: INYC_ARBOL_MES_TEMP
A52: INYC_ASI_DETALLE | B52: OUT_ASI_DETALLE_REP | D52: OUT_ASI_DETALLE_REP | E52: INYC_ASI_DETALLE
A53: INYC_ASI_E_DETALLE | B53: OUT_ASI_E_DETALLE_REP | D53: OUT_ASI_E_DETALLE_REP | E53: INYC_ASI_E_DETALLE
A54: INYC_ASI_E_RESUMEN | B54: OUT_ASI_E_RESUMEN_REP | D54: OUT_ASI_E_RESUMEN_REP | E54: INYC_ASI_E_RESUMEN
A55: INYC_ASI_RESUMEN | B55: OUT_ASI_RESUMEN_REP | D55: OUT_ASI_RESUMEN_REP | E55: INYC_ASI_RESUMEN
A56: INYC_LIQEXT_COMMISSION | B56: TEMP_LIQEXT_COMMISSION_FILE | D56: TEMP_LIQEXT_COMMISSION_FILE | E56: INYC_LIQEXT_COMMISSION
A57: INYC_LIQEXT_CREDIT_TEMP | B57: TEMP_LIQEXT_CREDIT_FILE | D57: TEMP_LIQEXT_CREDIT_FILE | E57: INYC_LIQEXT_CREDIT_TEMP
A58: INYC_AUTOLIQUIDACION_TEMP_DE | E58: INYC_AUTOLIQUIDACION_TEMP_DE
...
