Workbook

Sheet INFORMES
A1: SPRINT | B1: COD_INFORME | C1: DESC_INFORME | D1: TABLA | E1: F_INICIO | F1: F_FIN | G1: CARGA_TABLAS | H1: PUBLICACION | I1: FORMATO | J1: DESCRIPCION
A2: 1 | B2: 1.1 | C2: W-O - Rappel por Producción Resumen | D2: INYC_RPI_RESUMEN | E2: 20140101 | F2: 22000101 | G2: 1,2,3,4,5,6,7,8,9,10,11,12 | H2: 1,2,3,4,5,6,7,8,9,10,11,12 | I2: pdf | J2: RPI
A3: 1 | B3: 1.2 | C3: W-O - Rappel por Producción Detalle | D3: INYC_RPI_DETALLE | E3: 20140101 | F3: 20180101 | G3: 1,2,3,4,5,6,7,8,9,10,11,12 | H3: 1,2,3,4,5,6,7,8,9,10,11,12 | I3: excel | J3: RPI_DETALLE
A4: 2 | B4: 2.1 | C4: W-E - Rappel por Producción Resumen | D4: INYC_RAG_RESUMEN | E4: 20140101 | F4: 22000101 | G4: 1,2,3,4,5,6,7,8,9,10,11,12 | H4: 1,2,3,4,5,6,7,8,9,10,11,12 | I4: pdf | J4: RAG
A5: 2 | B5: 2.2 | C5: W-E - Rappel por Producción Detalle | D5: INYC_RAG_DETALLE | E5: 20140101 | F5: 20180101 | G5: 1,2,3,4,5,6,7,8,9,10,11,12 | H5: 1,2,3,4,5,6,7,8,9,10,11,12 | I5: excel | J5: RAG_DETALLE
A6: 0 | B6: 2.3 | C6: W-E - Rappel por producción Trimestral Resumen | D6: INYC_RAGT_RESUMEN | E6: 20190101 | F6: 22000101 | G6: 1,2,3,4,5,6,7,8,9,10,11,12 | H6: 1,2,3,4,5,6,7,8,9,10,11,12 | I6: pdf | J6: RAGT
A7: 2 | B7: 3.1 | C7: W-E - Rappel Producción Agentes Resumen | D7: INYC_RA_RESUMEN | E7: 20140101 | F7: 22000101 | G7: 1,2,3,4,5,6,7,8,9,10,11,12 | H7: 1,2,3,4,5,6,7,8,9,10,11,12 | I7: pdf | J7: RA
A8: 2 | B8: 3.2 | C8: W-E - Rappel Producción Agentes Detalle | D8: INYC_RA_DETALLE | E8: 20140101 | F8: 22000101 | G8: 1,2,3,4,5,6,7,8,9,10,11,12 | H8: 1,2,3,4,5,6,7,8,9,10,11,12 | I8: excel | J8: RA
A9: 2 | B9: 4.1 | C9: W-E - Ranking Concurso de Producción Anual | D9: INYC_CONCURSO | E9: 20140101 | F9: 22000101 | G9: 12 | H9: 12 | I9: pdf | J9: CONCURSO
A10: 2 | B10: 5.1 | C10: W-E - Incentivo Especial Anual | D10: INYC_INCENTIVO | E10: 20140101 | F10: 22000101 | G10: 12 | H10: 12 | I10: pdf | J10: INCENTIVO
A11: 2 | B11: 6.1 | C11: W-O - Rappel Producción Agentes Resumen | D11: INYC_RPA_RESUMEN | E11: 20140101 | F11: 22000101 | G11: 1,2,3,4,5,6,7,8,9,10,11,12 | H11: 1,2,3,4,5,6,7,8,9,10,11,12 | I11: pdf | J11: RPA
A12: 2 | B12: 6.2 | C12: W-O - Rappel Producción Agentes Detalle | D12: INYC_RPA_DETALLE | E12: 20140101 | F12: 22000101 | G12: 1,2,3,4,5,6,7,8,9,10,11,12 | H12: 1,2,3,4,5,6,7,8,9,10,11,12 | I12: excel | J12: RPA
A13: 3 | B13: 7.1 | C13: W-O - Diferenciales Resumen | D13: INYC_DIF_RESUMEN | E13: 20140101 | F13: 22000101 | G13: 1,2,3,4,5,6,7,8,9,10,11,12 | H13: 1,2,3,4,5,6,7,8,9,10,11,12 | I13: pdf | J13: DIF
A14: 3 | B14: 7.2 | C14: W-O - Diferenciales Detalle | D14: INYC_DIF_DETALLE | E14: 20140101 | F14: 20180101 | G14: 1,2,3,4,5,6,7,8,9,10,11,12 | H14: 1,2,3,4,5,6,7,8,9,10,11,12 | I14: excel | J14: DIF_DETALLE
A15: 3 | B15: 8.1 | C15: W-O - Incentivos por Cumplimiento de Objetivos y Liquidación a Cuenta Resumen | D15: INYC_COLC_RESUMEN | E15: 20140101 | F15: 22000101 | G15: 1,2,3,4,5,6,7,8,9,10,11,12 | H15: 3,6,9,12 | I15: pdf | J15: COLC
A16: 3 | B16: 8.2 | C16: W-O - Incentivos por Cumplimiento de Objetivos y Liquidación a Cuenta Detalle | D16: INYC_COLC_DETALLE | E16: 20140101 | F16: 20151001 | J16: OBSOLETO
A17: 3 | B17: 9.1 | C17: W-O - Compensación por Transporte Resumen | D17: INYC_CT_RESUMEN | E17: 20140101 | F17: 20151001 | J17: OBSOLETO
A18: 3 | B18: 9.2 | C18: W-O - Compensación por Transporte Detalle | D18: INYC_CT_DETALLE | E18: 20140101 | F18: 20151001 | J18: OBSOLETO
A19: 3 | B19: 10.1 | C19: W-O - Rappel Defensa Cartera Resumen | D19: INYC_RDC_RESUMEN | E19: 20140101 | F19: 22000101 | G19: 1,2,3,4,5,6,7,8,9,10,11,12 | H19: 1,2,3,4,5,6,7,8,9,10,11,12 | I19: pdf | J19: RDC
A20: 3 | B20: 10.2 | C20: W-O - Rappel Defensa Cartera Detalle | D20: INYC_RDC_DETALLE | E20: 20140101 | F20: 22000101 | G20: 1,2,3,4,5,6,7,8,9,10,11,12 | H20: 1,2,3,4,5,6,7,8,9,10,11,12 | I20: excel | J20: RDC
A21: 3 | B21: 11.1 | C21: W-O - Incentivo Rappel Especial Pre-Plan Resumen | D21: INYC_IPP_RESUMEN | E21: 20140101 | F21: 20170101 | J21: OBSOLETO
A22: 3 | B22: 12.1 | C22: W-O - Anulaciones de Primer Año Resumen | D22: INYC_AN1_RESUMEN | E22: 20170101 | F22: 22000101 | G22: 12 | H22: 12 | I22: pdf | J22: AN
A23: 3 | B23: 12.2 | C23: W-O - Anulaciones de Segundo Año Resumen | D23: INYC_AN2_RESUMEN | E23: 20170101 | F23: 22000101 | G23: 12 | H23: 12 | I23: pdf | J23: AN
A24: 3 | B24: 13.1 | C24: W-E - Diferenciales Resumen | D24: INYC_DIF_E_RESUMEN | E24: 20140101 | F24: 22000101 | G24: 1,2,3,4,5,6,7,8,9,10,11,12 | H24: 1,2,3,4,5,6,7,8,9,10,11,12 | I24: pdf | J24: DIF_E
A25: 3 | B25: 13.2 | C25: W-E - Diferenciales Detalle | D25: INYC_DIF_E_DETALLE | E25: 20140101 | F25: 20180101 | G25: 1,2,3,4,5,6,7,8,9,10,11,12 | H25: 1,2,3,4,5,6,7,8,9,10,11,12 | I25: excel | J25: DIF_E_DETALLE
A26: 3 | B26: 14.1 | C26: W-O - Producción Propia Agentes con Grupo Resumen | D26: INYC_PP_RESUMEN | E26: 20140101 | F26: 22000101 | G26: 1,2,3,4,5,6,7,8,9,10,11,12 | H26: 3,4,5,6,7,8,9,10,11,12 | I26: pdf | J26: PP
A27: 3 | B27: 14.2 | C27: W-O - Producción Propia Agentes con Grupo Detalle | D27: INYC_PP_DETALLE | E27: 20200101 | F27: 22000101 | G27: 1,2,3,4,5,6,7,8,9,10,11,12 | H27: 3,4,5,6,7,8,9,10,11,12 | I27: pdf | J27: PP
A28: 3 | B28: 15.1 | C28: W-O - Rappel Incremento de Prima y Pólizas | D28: INYC_RIN_RESUMEN | E28: 20140101 | F28: 22000101 | G28: 1.12 | H28: 1 | I28: pdf | J28: RIP
A29: 3 | B29: 16.1 | C29: W-O - Financiación Agentes Plan de Carrera Resumen | D29: INYC_FIN_RESUMEN | E29: 20140101 | F29: 20180201 | G29: 1,2,3,4,5,6,7,8,9,10,11,12 | H29: 1,2,3,4,5,6,7,8,9,10,11,12 | I29: pdf | J29: FIN
A30: 4 | B30: 17.1 | C30: W-O - Rappel Especial Resumen | D30: INYC_RE_RESUMEN | E30: 20140101 | F30: 22000101 | G30: 1,2,3,4,5,6,7,8,9,10,11,12 | H30: 1,2,3,4,5,6,7,8,9,10,11,12 | I30: pdf | J30: RE
A31: 4 | B31: 17.2 | C31: W-O - Rappel Especial Detalle | D31: INYC_RE_DETALLE | E31: 20140101 | F31: 22000101 | G31: 1,2,3,4,5,6,7,8,9,10,11,12 | H31: 1,2,3,4,5,6,7,8,9,10,11,12 | I31: excel | J31: RE
A32: 4 | B32: 18.1 | C32: W-O - Producción Comunidades Resumen | D32: INYC_COMU_RESUMEN | E32: 20140101 | F32: 20180101 | G32: 1,2,3,4,5,6,7,8,9,10,11,12 | H32: 6,7,8,9,10,11,12 | I32: pdf | J32: COMU
A33: 4 | B33: 19.1 | C33: W-O - Rappel Asistencias Resumen | D33: INYC_ASI_RESUMEN | E33: 20140101 | F33: 22000101 | G33: 1,2,3,4,5,6,7,8,9,10,11,12 | H33: 1,2,3,4,5,6,7,8,9,10,11,12 | I33: pdf | J33: ASI
A34: SOP-PE000104 | B34: 19.2 | C34: W-O - Rappel Asistencias Detalle | D34: INYC_ASI_DETALLE | E34: 20140101 | F34: 22000101 | G34: 1,2,3,4,5,6,7,8,9,10,11,12 | H34: 1,2,3,4,5,6,7,8,9,10,11,12 | I34: excel | J34: ASI
A35: 4 | B35: 20.1 | C35: W-E - Rappel Asistencias Resumen | D35: INYC_ASI_E_RESUMEN | E35: 20140101 | F35: 22000101 | G35: 1,2,3,4,5,6,7,8,9,10,11,12 | H35: 1,2,3,4,5,6,7,8,9,10,11,12 | I35: pdf | J35: ASI_E
A36: SOP-PE000104 | B36: 20.2 | C36: W-E - Rappel Asistencias Detalle | D36: INYC_ASI_E_DETALLE | E36: 20140101 | F36: 22000101 | G36: 1,2,3,4,5,6,7,8,9,10,11,12 | H36: 1,2,3,4,5,6,7,8,9,10,11,12 | I36: excel | J36: ASI_E
A37: 4 | B37: 21.1 | C37: W-O - Rappel Acción Comercial Hogar Resumen | D37: INYC_RACH_RESUMEN | E37: 20140101 | F37: 22000101 | G37: 2,3,4,5,6,7,9 | H37: 2,3,4,5,6,7,9 | I37: pdf | J37: RACH
A38: 4 | B38: 22.1 | C38: W-O - Mínimos Garantizados Resumen | D38: INYC_MIN_RESUMEN | E38: 20140101 | F38: 22000101 | G38: 1,2,3,4,5,6,7,8,9,10,11,12 | H38: 1,2,3,4,5,6,7,8,9,10,11,12 | I38: pdf | J38: MIN
A39: 4 | B39: 23.1 | C39: W-O - Rappel Actividad Agentes con Grupo -Liquidación a Cuenta- Resumen | D39: INYC_REA_RESUMEN | E39: 20140101 | F39: 22000101 | G39: 1,2,3,4,5,6,7,8,9,10,11,12 | H39: 3,6,9,12 | I39: pdf | J39: REA
A40: 4 | B40: 24.1 | C40: W-O - Rappel Incremento Pólizas en Cartera Resumen | D40: INYC_RIP_RESUMEN | E40: 20140101 | F40: 22000101 | G40: 1,2,3,4,5,6,7,8,9,10,11,12 | H40: 1,2,3,4,5,6,7,8,9,10,11,12 | I40: pdf | J40: RIN
...

Sheet INSERT INFORMES
A1: =IF(INFORMES!J2="OBSOLETO","","INSERT INTO INYCEXT.INYC_CONF_INFORMES (COD_INFORME,DESC_INFORME,TABLA,F_INICIO,F_FIN,CARGA_TABLAS,PUBLICACION,FORMATO,DESCRIPCION) VALUES ("&INFORMES!B2&",'"&INFORMES!C2&"','"&INFORMES!D2&"',TO_DATE('"&INFORMES!E2&"','yyyymmdd'),TO_DATE('"&INFORMES!F2&"','yyyymmdd'),'"&INFORMES!G2&"','"&INFORMES!H2&"','"&INFORMES!I2&"','"&INFORMES!J2&"');") -> INSERT INTO INYCEXT.INYC_CONF_INFORMES (COD_INFORME,DESC_INFORME,TABLA,F_INICIO,F_FIN,CARGA_TABLAS,PUBLICACION,FORMATO,DESCRIPCION) VALUES (1.1,'W-O - Rappel por Producción Resumen','INYC_RPI_RESUMEN',TO_DATE('20140101','yyyymmdd'),TO_DATE('22000101','yyyymmdd'),'1,2,3,4,5,6,7,8,9,10,11,12','1,2,3,4,5,6,7,8,9,10,11,12','pdf','RPI'); | B1: =IF(INFORMES!J2="OBSOLETO","","INSERT INTO INYCEXT.INYC_CONF_INFORMES@tc_link (COD_INFORME,DESC_INFORME,TABLA,F_INICIO,F_FIN,CARGA_TABLAS,PUBLICACION,FORMATO,DESCRIPCION) VALUES ("&INFORMES!B2&",'"&INFORMES!C2&"','"&INFORMES!D2&"',TO_DATE('"&INFORMES!E2&"','yyyymmdd'),TO_DATE('"&INFORMES!F2&"','yyyymmdd'),'"&INFORMES!G2&"','"&INFORMES!H2&"','"&INFORMES!I2&"','"&INFORMES!J2&"');") -> INSERT INTO INYCEXT.INYC_CONF_INFORMES@tc_link (COD_INFORME,DESC_INFORME,TABLA,F_INICIO,F_FIN,CARGA_TABLAS,PUBLICACION,FORMATO,DESCRIPCION) VALUES (1.1,'W-O - Rappel por Producción Resumen','INYC_RPI_RESUMEN',TO_DATE('20140101','yyyymmdd'),TO_DATE('22000101','yyyymmdd'),'1,2,3,4,5,6,7,8,9,10,11,12','1,2,3,4,5,6,7,8,9,10,11,12','pdf','RPI');
A2: =IF(INFORMES!J3="OBSOLETO","","INSERT INTO INYCEXT.INYC_CONF_INFORMES (COD_INFORME,DESC_INFORME,TABLA,F_INICIO,F_FIN,CARGA_TABLAS,PUBLICACION,FORMATO,DESCRIPCION) VALUES ("&INFORMES!B3&",'"&INFORMES!C3&"','"&INFORMES!D3&"',TO_DATE('"&INFORMES!E3&"','yyyymmdd'),TO_DATE('"&INFORMES!F3&"','yyyymmdd'),'"&INFORMES!G3&"','"&INFORMES!H3&"','"&INFORMES!I3&"','"&INFORMES!J3&"');") -> INSERT INTO INYCEXT.INYC_CONF_INFORMES (COD_INFORME,DESC_INFORME,TABLA,F_INICIO,F_FIN,CARGA_TABLAS,PUBLICACION,FORMATO,DESCRIPCION) VALUES (1.2,'W-O - Rappel por Producción Detalle','INYC_RPI_DETALLE',TO_DATE('20140101','yyyymmdd'),TO_DATE('20180101','yyyymmdd'),'1,2,3,4,5,6,7,8,9,10,11,12','1,2,3,4,5,6,7,8,9,10,11,12','excel','RPI_DETALLE'); | B2: =IF(INFORMES!J3="OBSOLETO","","INSERT INTO INYCEXT.INYC_CONF_INFORMES@tc_link (COD_INFORME,DESC_INFORME,TABLA,F_INICIO,F_FIN,CARGA_TABLAS,PUBLICACION,FORMATO,DESCRIPCION) VALUES ("&INFORMES!B3&",'"&INFORMES!C3&"','"&INFORMES!D3&"',TO_DATE('"&INFORMES!E3&"','yyyymmdd'),TO_DATE('"&INFORMES!F3&"','yyyymmdd'),'"&INFORMES!G3&"','"&INFORMES!H3&"','"&INFORMES!I3&"','"&INFORMES!J3&"');") -> INSERT INTO INYCEXT.INYC_CONF_INFORMES@tc_link (COD_INFORME,DESC_INFORME,TABLA,F_INICIO,F_FIN,CARGA_TABLAS,PUBLICACION,FORMATO,DESCRIPCION) VALUES (1.2,'W-O - Rappel por Producción Detalle','INYC_RPI_DETALLE',TO_DATE('20140101','yyyymmdd'),TO_DATE('20180101','yyyymmdd'),'1,2,3,4,5,6,7,8,9,10,11,12','1,2,3,4,5,6,7,8,9,10,11,12','excel','RPI_DETALLE');
A3: =IF(INFORMES!J4="OBSOLETO","","INSERT INTO INYCEXT.INYC_CONF_INFORMES (COD_INFORME,DESC_INFORME,TABLA,F_INICIO,F_FIN,CARGA_TABLAS,PUBLICACION,FORMATO,DESCRIPCION) VALUES ("&INFORMES!B4&",'"&INFORMES!C4&"','"&INFORMES!D4&"',TO_DATE('"&INFORMES!E4&"','yyyymmdd'),TO_DATE('"&INFORMES!F4&"','yyyymmdd'),'"&INFORMES!G4&"','"&INFORMES!H4&"','"&INFORMES!I4&"','"&INFORMES!J4&"');") -> INSERT INTO INYCEXT.INYC_CONF_INFORMES (COD_INFORME,DESC_INFORME,TABLA,F_INICIO,F_FIN,CARGA_TABLAS,PUBLICACION,FORMATO,DESCRIPCION) VALUES (2.1,'W-E - Rappel por Producción Resumen','INYC_RAG_RESUMEN',TO_DATE('20140101','yyyymmdd'),TO_DATE('22000101','yyyymmdd'),'1,2,3,4,5,6,7,8,9,10,11,12','1,2,3,4,5,6,7,8,9,10,11,12','pdf','RAG'); | B3: =IF(INFORMES!J4="OBSOLETO","","INSERT INTO INYCEXT.INYC_CONF_INFORMES@tc_link (COD_INFORME,DESC_INFORME,TABLA,F_INICIO,F_FIN,CARGA_TABLAS,PUBLICACION,FORMATO,DESCRIPCION) VALUES ("&INFORMES!B4&",'"&INFORMES!C4&"','"&INFORMES!D4&"',TO_DATE('"&INFORMES!E4&"','yyyymmdd'),TO_DATE('"&INFORMES!F4&"','yyyymmdd'),'"&INFORMES!G4&"','"&INFORMES!H4&"','"&INFORMES!I4&"','"&INFORMES!J4&"');") -> INSERT INTO INYCEXT.INYC_CONF_INFORMES@tc_link (COD_INFORME,DESC_INFORME,TABLA,F_INICIO,F_FIN,CARGA_TABLAS,PUBLICACION,FORMATO,DESCRIPCION) VALUES (2.1,'W-E - Rappel por Producción Resumen','INYC_RAG_RESUMEN',TO_DATE('20140101','yyyymmdd'),TO_DATE('22000101','yyyymmdd'),'1,2,3,4,5,6,7,8,9,10,11,12','1,2,3,4,5,6,7,8,9,10,11,12','pdf','RAG');
A4: =IF(INFORMES!J5="OBSOLETO","","INSERT INTO INYCEXT.INYC_CONF_INFORMES (COD_INFORME,DESC_INFORME,TABLA,F_INICIO,F_FIN,CARGA_TABLAS,PUBLICACION,FORMATO,DESCRIPCION) VALUES ("&INFORMES!B5&",'"&INFORMES!C5&"','"&INFORMES!D5&"',TO_DATE('"&INFORMES!E5&"','yyyymmdd'),TO_DATE('"&INFORMES!F5&"','yyyymmdd'),'"&INFORMES!G5&"','"&INFORMES!H5&"','"&INFORMES!I5&"','"&INFORMES!J5&"');") -> INSERT INTO INYCEXT.INYC_CONF_INFORMES (COD_INFORME,DESC_INFORME,TABLA,F_INICIO,F_FIN,CARGA_TABLAS,PUBLICACION,FORMATO,DESCRIPCION) VALUES (2.2,'W-E - Rappel por Producción Detalle','INYC_RAG_DETALLE',TO_DATE('20140101','yyyymmdd'),TO_DATE('20180101','yyyymmdd'),'1,2,3,4,5,6,7,8,9,10,11,12','1,2,3,4,5,6,7,8,9,10,11,12','excel','RAG_DETALLE'); | B4: =IF(INFORMES!J5="OBSOLETO","","INSERT INTO INYCEXT.INYC_CONF_INFORMES@tc_link (COD_INFORME,DESC_INFORME,TABLA,F_INICIO,F_FIN,CARGA_TABLAS,PUBLICACION,FORMATO,DESCRIPCION) VALUES ("&INFORMES!B5&",'"&INFORMES!C5&"','"&INFORMES!D5&"',TO_DATE('"&INFORMES!E5&"','yyyymmdd'),TO_DATE('"&INFORMES!F5&"','yyyymmdd'),'"&INFORMES!G5&"','"&INFORMES!H5&"','"&INFORMES!I5&"','"&INFORMES!J5&"');") -> INSERT INTO INYCEXT.INYC_CONF_INFORMES@tc_link (COD_INFORME,DESC_INFORME,TABLA,F_INICIO,F_FIN,CARGA_TABLAS,PUBLICACION,FORMATO,DESCRIPCION) VALUES (2.2,'W-E - Rappel por Producción Detalle','INYC_RAG_DETALLE',TO_DATE('20140101','yyyymmdd'),TO_DATE('20180101','yyyymmdd'),'1,2,3,4,5,6,7,8,9,10,11,12','1,2,3,4,5,6,7,8,9,10,11,12','excel','RAG_DETALLE');
A5: =IF(INFORMES!J6="OBSOLETO","","INSERT INTO INYCEXT.INYC_CONF_INFORMES (COD_INFORME,DESC_INFORME,TABLA,F_INICIO,F_FIN,CARGA_TABLAS,PUBLICACION,FORMATO,DESCRIPCION) VALUES ("&INFORMES!B6&",'"&INFORMES!C6&"','"&INFORMES!D6&"',TO_DATE('"&INFORMES!E6&"','yyyymmdd'),TO_DATE('"&INFORMES!F6&"','yyyymmdd'),'"&INFORMES!G6&"','"&INFORMES!H6&"','"&INFORMES!I6&"','"&INFORMES!J6&"');") -> INSERT INTO INYCEXT.INYC_CONF_INFORMES (COD_INFORME,DESC_INFORME,TABLA,F_INICIO,F_FIN,CARGA_TABLAS,PUBLICACION,FORMATO,DESCRIPCION) VALUES (2.3,'W-E - Rappel por producción Trimestral Resumen','INYC_RAGT_RESUMEN',TO_DATE('20190101','yyyymmdd'),TO_DATE('22000101','yyyymmdd'),'1,2,3,4,5,6,7,8,9,10,11,12','1,2,3,4,5,6,7,8,9,10,11,12','pdf','RAGT'); | B5: =IF(INFORMES!J6="OBSOLETO","","INSERT INTO INYCEXT.INYC_CONF_INFORMES@tc_link (COD_INFORME,DESC_INFORME,TABLA,F_INICIO,F_FIN,CARGA_TABLAS,PUBLICACION,FORMATO,DESCRIPCION) VALUES ("&INFORMES!B6&",'"&INFORMES!C6&"','"&INFORMES!D6&"',TO_DATE('"&INFORMES!E6&"','yyyymmdd'),TO_DATE('"&INFORMES!F6&"','yyyymmdd'),'"&INFORMES!G6&"','"&INFORMES!H6&"','"&INFORMES!I6&"','"&INFORMES!J6&"');") -> INSERT INTO INYCEXT.INYC_CONF_INFORMES@tc_link (COD_INFORME,DESC_INFORME,TABLA,F_INICIO,F_FIN,CARGA_TABLAS,PUBLICACION,FORMATO,DESCRIPCION) VALUES (2.3,'W-E - Rappel por producción Trimestral Resumen','INYC_RAGT_RESUMEN',TO_DATE('20190101','yyyymmdd'),TO_DATE('22000101','yyyymmdd'),'1,2,3,4,5,6,7,8,9,10,11,12','1,2,3,4,5,6,7,8,9,10,11,12','pdf','RAGT');
A6: =IF(INFORMES!J7="OBSOLETO","","INSERT INTO INYCEXT.INYC_CONF_INFORMES (COD_INFORME,DESC_INFORME,TABLA,F_INICIO,F_FIN,CARGA_TABLAS,PUBLICACION,FORMATO,DESCRIPCION) VALUES ("&INFORMES!B7&",'"&INFORMES!C7&"','"&INFORMES!D7&"',TO_DATE('"&INFORMES!E7&"','yyyymmdd'),TO_DATE('"&INFORMES!F7&"','yyyymmdd'),'"&INFORMES!G7&"','"&INFORMES!H7&"','"&INFORMES!I7&"','"&INFORMES!J7&"');") -> INSERT INTO INYCEXT.INYC_CONF_INFORMES (COD_INFORME,DESC_INFORME,TABLA,F_INICIO,F_FIN,CARGA_TABLAS,PUBLICACION,FORMATO,DESCRIPCION) VALUES (3.1,'W-E - Rappel Producción Agentes Resumen','INYC_RA_RESUMEN',TO_DATE('20140101','yyyymmdd'),TO_DATE('22000101','yyyymmdd'),'1,2,3,4,5,6,7,8,9,10,11,12','1,2,3,4,5,6,7,8,9,10,11,12','pdf','RA'); | B6: =IF(INFORMES!J7="OBSOLETO","","INSERT INTO INYCEXT.INYC_CONF_INFORMES@tc_link (COD_INFORME,DESC_INFORME,TABLA,F_INICIO,F_FIN,CARGA_TABLAS,PUBLICACION,FORMATO,DESCRIPCION) VALUES ("&INFORMES!B7&",'"&INFORMES!C7&"','"&INFORMES!D7&"',TO_DATE('"&INFORMES!E7&"','yyyymmdd'),TO_DATE('"&INFORMES!F7&"','yyyymmdd'),'"&INFORMES!G7&"','"&INFORMES!H7&"','"&INFORMES!I7&"','"&INFORMES!J7&"');") -> INSERT INTO INYCEXT.INYC_CONF_INFORMES@tc_link (COD_INFORME,DESC_INFORME,TABLA,F_INICIO,F_FIN,CARGA_TABLAS,PUBLICACION,FORMATO,DESCRIPCION) VALUES (3.1,'W-E - Rappel Producción Agentes Resumen','INYC_RA_RESUMEN',TO_DATE('20140101','yyyymmdd'),TO_DATE('22000101','yyyymmdd'),'1,2,3,4,5,6,7,8,9,10,11,12','1,2,3,4,5,6,7,8,9,10,11,12','pdf','RA');
A7: =IF(INFORMES!J8="OBSOLETO","","INSERT INTO INYCEXT.INYC_CONF_INFORMES (COD_INFORME,DESC_INFORME,TABLA,F_INICIO,F_FIN,CARGA_TABLAS,PUBLICACION,FORMATO,DESCRIPCION) VALUES ("&INFORMES!B8&",'"&INFORMES!C8&"','"&INFORMES!D8&"',TO_DATE('"&INFORMES!E8&"','yyyymmdd'),TO_DATE('"&INFORMES!F8&"','yyyymmdd'),'"&INFORMES!G8&"','"&INFORMES!H8&"','"&INFORMES!I8&"','"&INFORMES!J8&"');") -> INSERT INTO INYCEXT.INYC_CONF_INFORMES (COD_INFORME,DESC_INFORME,TABLA,F_INICIO,F_FIN,CARGA_TABLAS,PUBLICACION,FORMATO,DESCRIPCION) VALUES (3.2,'W-E - Rappel Producción Agentes Detalle','INYC_RA_DETALLE',TO_DATE('20140101','yyyymmdd'),TO_DATE('22000101','yyyymmdd'),'1,2,3,4,5,6,7,8,9,10,11,12','1,2,3,4,5,6,7,8,9,10,11,12','excel','RA'); | B7: =IF(INFORMES!J8="OBSOLETO","","INSERT INTO INYCEXT.INYC_CONF_INFORMES@tc_link (COD_INFORME,DESC_INFORME,TABLA,F_INICIO,F_FIN,CARGA_TABLAS,PUBLICACION,FORMATO,DESCRIPCION) VALUES ("&INFORMES!B8&",'"&INFORMES!C8&"','"&INFORMES!D8&"',TO_DATE('"&INFORMES!E8&"','yyyymmdd'),TO_DATE('"&INFORMES!F8&"','yyyymmdd'),'"&INFORMES!G8&"','"&INFORMES!H8&"','"&INFORMES!I8&"','"&INFORMES!J8&"');") -> INSERT INTO INYCEXT.INYC_CONF_INFORMES@tc_link (COD_INFORME,DESC_INFORME,TABLA,F_INICIO,F_FIN,CARGA_TABLAS,PUBLICACION,FORMATO,DESCRIPCION) VALUES (3.2,'W-E - Rappel Producción Agentes Detalle','INYC_RA_DETALLE',TO_DATE('20140101','yyyymmdd'),TO_DATE('22000101','yyyymmdd'),'1,2,3,4,5,6,7,8,9,10,11,12','1,2,3,4,5,6,7,8,9,10,11,12','excel','RA');
A8: =IF(INFORMES!J9="OBSOLETO","","INSERT INTO INYCEXT.INYC_CONF_INFORMES (COD_INFORME,DESC_INFORME,TABLA,F_INICIO,F_FIN,CARGA_TABLAS,PUBLICACION,FORMATO,DESCRIPCION) VALUES ("&INFORMES!B9&",'"&INFORMES!C9&"','"&INFORMES!D9&"',TO_DATE('"&INFORMES!E9&"','yyyymmdd'),TO_DATE('"&INFORMES!F9&"','yyyymmdd'),'"&INFORMES!G9&"','"&INFORMES!H9&"','"&INFORMES!I9&"','"&INFORMES!J9&"');") -> INSERT INTO INYCEXT.INYC_CONF_INFORMES (COD_INFORME,DESC_INFORME,TABLA,F_INICIO,F_FIN,CARGA_TABLAS,PUBLICACION,FORMATO,DESCRIPCION) VALUES (4.1,'W-E - Ranking Concurso de Producción Anual','INYC_CONCURSO',TO_DATE('20140101','yyyymmdd'),TO_DATE('22000101','yyyymmdd'),'12','12','pdf','CONCURSO'); | B8: =IF(INFORMES!J9="OBSOLETO","","INSERT INTO INYCEXT.INYC_CONF_INFORMES@tc_link (COD_INFORME,DESC_INFORME,TABLA,F_INICIO,F_FIN,CARGA_TABLAS,PUBLICACION,FORMATO,DESCRIPCION) VALUES ("&INFORMES!B9&",'"&INFORMES!C9&"','"&INFORMES!D9&"',TO_DATE('"&INFORMES!E9&"','yyyymmdd'),TO_DATE('"&INFORMES!F9&"','yyyymmdd'),'"&INFORMES!G9&"','"&INFORMES!H9&"','"&INFORMES!I9&"','"&INFORMES!J9&"');") -> INSERT INTO INYCEXT.INYC_CONF_INFORMES@tc_link (COD_INFORME,DESC_INFORME,TABLA,F_INICIO,F_FIN,CARGA_TABLAS,PUBLICACION,FORMATO,DESCRIPCION) VALUES (4.1,'W-E - Ranking Concurso de Producción Anual','INYC_CONCURSO',TO_DATE('20140101','yyyymmdd'),TO_DATE('22000101','yyyymmdd'),'12','12','pdf','CONCURSO');
A9: =IF(INFORMES!J10="OBSOLETO","","INSERT INTO INYCEXT.INYC_CONF_INFORMES (COD_INFORME,DESC_INFORME,TABLA,F_INICIO,F_FIN,CARGA_TABLAS,PUBLICACION,FORMATO,DESCRIPCION) VALUES ("&INFORMES!B10&",'"&INFORMES!C10&"','"&INFORMES!D10&"',TO_DATE('"&INFORMES!E10&"','yyyymmdd'),TO_DATE('"&INFORMES!F10&"','yyyymmdd'),'"&INFORMES!G10&"','"&INFORMES!H10&"','"&INFORMES!I10&"','"&INFORMES!J10&"');") -> INSERT INTO INYCEXT.INYC_CONF_INFORMES (COD_INFORME,DESC_INFORME,TABLA,F_INICIO,F_FIN,CARGA_TABLAS,PUBLICACION,FORMATO,DESCRIPCION) VALUES (5.1,'W-E - Incentivo Especial Anual','INYC_INCENTIVO',TO_DATE('20140101','yyyymmdd'),TO_DATE('22000101','yyyymmdd'),'12','12','pdf','INCENTIVO'); | B9: =IF(INFORMES!J10="OBSOLETO","","INSERT INTO INYCEXT.INYC_CONF_INFORMES@tc_link (COD_INFORME,DESC_INFORME,TABLA,F_INICIO,F_FIN,CARGA_TABLAS,PUBLICACION,FORMATO,DESCRIPCION) VALUES ("&INFORMES!B10&",'"&INFORMES!C10&"','"&INFORMES!D10&"',TO_DATE('"&INFORMES!E10&"','yyyymmdd'),TO_DATE('"&INFORMES!F10&"','yyyymmdd'),'"&INFORMES!G10&"','"&INFORMES!H10&"','"&INFORMES!I10&"','"&INFORMES!J10&"');") -> INSERT INTO INYCEXT.INYC_CONF_INFORMES@tc_link (COD_INFORME,DESC_INFORME,TABLA,F_INICIO,F_FIN,CARGA_TABLAS,PUBLICACION,FORMATO,DESCRIPCION) VALUES (5.1,'W-E - Incentivo Especial Anual','INYC_INCENTIVO',TO_DATE('20140101','yyyymmdd'),TO_DATE('22000101','yyyymmdd'),'12','12','pdf','INCENTIVO');
A10: =IF(INFORMES!J11="OBSOLETO","","INSERT INTO INYCEXT.INYC_CONF_INFORMES (COD_INFORME,DESC_INFORME,TABLA,F_INICIO,F_FIN,CARGA_TABLAS,PUBLICACION,FORMATO,DESCRIPCION) VALUES ("&INFORMES!B11&",'"&INFORMES!C11&"','"&INFORMES!D11&"',TO_DATE('"&INFORMES!E11&"','yyyymmdd'),TO_DATE('"&INFORMES!F11&"','yyyymmdd'),'"&INFORMES!G11&"','"&INFORMES!H11&"','"&INFORMES!I11&"','"&INFORMES!J11&"');") -> INSERT INTO INYCEXT.INYC_CONF_INFORMES (COD_INFORME,DESC_INFORME,TABLA,F_INICIO,F_FIN,CARGA_TABLAS,PUBLICACION,FORMATO,DESCRIPCION) VALUES (6.1,'W-O - Rappel Producción Agentes Resumen','INYC_RPA_RESUMEN',TO_DATE('20140101','yyyymmdd'),TO_DATE('22000101','yyyymmdd'),'1,2,3,4,5,6,7,8,9,10,11,12','1,2,3,4,5,6,7,8,9,10,11,12','pdf','RPA'); | B10: =IF(INFORMES!J11="OBSOLETO","","INSERT INTO INYCEXT.INYC_CONF_INFORMES@tc_link (COD_INFORME,DESC_INFORME,TABLA,F_INICIO,F_FIN,CARGA_TABLAS,PUBLICACION,FORMATO,DESCRIPCION) VALUES ("&INFORMES!B11&",'"&INFORMES!C11&"','"&INFORMES!D11&"',TO_DATE('"&INFORMES!E11&"','yyyymmdd'),TO_DATE('"&INFORMES!F11&"','yyyymmdd'),'"&INFORMES!G11&"','"&INFORMES!H11&"','"&INFORMES!I11&"','"&INFORMES!J11&"');") -> INSERT INTO INYCEXT.INYC_CONF_INFORMES@tc_link (COD_INFORME,DESC_INFORME,TABLA,F_INICIO,F_FIN,CARGA_TABLAS,PUBLICACION,FORMATO,DESCRIPCION) VALUES (6.1,'W-O - Rappel Producción Agentes Resumen','INYC_RPA_RESUMEN',TO_DATE('20140101','yyyymmdd'),TO_DATE('22000101','yyyymmdd'),'1,2,3,4,5,6,7,8,9,10,11,12','1,2,3,4,5,6,7,8,9,10,11,12','pdf','RPA');
A11: =IF(INFORMES!J12="OBSOLETO","","INSERT INTO INYCEXT.INYC_CONF_INFORMES (COD_INFORME,DESC_INFORME,TABLA,F_INICIO,F_FIN,CARGA_TABLAS,PUBLICACION,FORMATO,DESCRIPCION) VALUES ("&INFORMES!B12&",'"&INFORMES!C12&"','"&INFORMES!D12&"',TO_DATE('"&INFORMES!E12&"','yyyymmdd'),TO_DATE('"&INFORMES!F12&"','yyyymmdd'),'"&INFORMES!G12&"','"&INFORMES!H12&"','"&INFORMES!I12&"','"&INFORMES!J12&"');") -> INSERT INTO INYCEXT.INYC_CONF_INFORMES (COD_INFORME,DESC_INFORME,TABLA,F_INICIO,F_FIN,CARGA_TABLAS,PUBLICACION,FORMATO,DESCRIPCION) VALUES (6.2,'W-O - Rappel Producción Agentes Detalle','INYC_RPA_DETALLE',TO_DATE('20140101','yyyymmdd'),TO_DATE('22000101','yyyymmdd'),'1,2,3,4,5,6,7,8,9,10,11,12','1,2,3,4,5,6,7,8,9,10,11,12','excel','RPA'); | B11: =IF(INFORMES!J12="OBSOLETO","","INSERT INTO INYCEXT.INYC_CONF_INFORMES@tc_link (COD_INFORME,DESC_INFORME,TABLA,F_INICIO,F_FIN,CARGA_TABLAS,PUBLICACION,FORMATO,DESCRIPCION) VALUES ("&INFORMES!B12&",'"&INFORMES!C12&"','"&INFORMES!D12&"',TO_DATE('"&INFORMES!E12&"','yyyymmdd'),TO_DATE('"&INFORMES!F12&"','yyyymmdd'),'"&INFORMES!G12&"','"&INFORMES!H12&"','"&INFORMES!I12&"','"&INFORMES!J12&"');") -> INSERT INTO INYCEXT.INYC_CONF_INFORMES@tc_link (COD_INFORME,DESC_INFORME,TABLA,F_INICIO,F_FIN,CARGA_TABLAS,PUBLICACION,FORMATO,DESCRIPCION) VALUES (6.2,'W-O - Rappel Producción Agentes Detalle','INYC_RPA_DETALLE',TO_DATE('20140101','yyyymmdd'),TO_DATE('22000101','yyyymmdd'),'1,2,3,4,5,6,7,8,9,10,11,12','1,2,3,4,5,6,7,8,9,10,11,12','excel','RPA');
A12: =IF(INFORMES!J13="OBSOLETO","","INSERT INTO INYCEXT.INYC_CONF_INFORMES (COD_INFORME,DESC_INFORME,TABLA,F_INICIO,F_FIN,CARGA_TABLAS,PUBLICACION,FORMATO,DESCRIPCION) VALUES ("&INFORMES!B13&",'"&INFORMES!C13&"','"&INFORMES!D13&"',TO_DATE('"&INFORMES!E13&"','yyyymmdd'),TO_DATE('"&INFORMES!F13&"','yyyymmdd'),'"&INFORMES!G13&"','"&INFORMES!H13&"','"&INFORMES!I13&"','"&INFORMES!J13&"');") -> INSERT INTO INYCEXT.INYC_CONF_INFORMES (COD_INFORME,DESC_INFORME,TABLA,F_INICIO,F_FIN,CARGA_TABLAS,PUBLICACION,FORMATO,DESCRIPCION) VALUES (7.1,'W-O - Diferenciales Resumen','INYC_DIF_RESUMEN',TO_DATE('20140101','yyyymmdd'),TO_DATE('22000101','yyyymmdd'),'1,2,3,4,5,6,7,8,9,10,11,12','1,2,3,4,5,6,7,8,9,10,11,12','pdf','DIF'); | B12: =IF(INFORMES!J13="OBSOLETO","","INSERT INTO INYCEXT.INYC_CONF_INFORMES@tc_link (COD_INFORME,DESC_INFORME,TABLA,F_INICIO,F_FIN,CARGA_TABLAS,PUBLICACION,FORMATO,DESCRIPCION) VALUES ("&INFORMES!B13&",'"&INFORMES!C13&"','"&INFORMES!D13&"',TO_DATE('"&INFORMES!E13&"','yyyymmdd'),TO_DATE('"&INFORMES!F13&"','yyyymmdd'),'"&INFORMES!G13&"','"&INFORMES!H13&"','"&INFORMES!I13&"','"&INFORMES!J13&"');") -> INSERT INTO INYCEXT.INYC_CONF_INFORMES@tc_link (COD_INFORME,DESC_INFORME,TABLA,F_INICIO,F_FIN,CARGA_TABLAS,PUBLICACION,FORMATO,DESCRIPCION) VALUES (7.1,'W-O - Diferenciales Resumen','INYC_DIF_RESUMEN',TO_DATE('20140101','yyyymmdd'),TO_DATE('22000101','yyyymmdd'),'1,2,3,4,5,6,7,8,9,10,11,12','1,2,3,4,5,6,7,8,9,10,11,12','pdf','DIF');
... A80: =IF(INFORMES!J81="OBSOLETO","","INSERT INTO INYCEXT.INYC_CONF_INFORMES (COD_INFORME,DESC_INFORME,TABLA,F_INICIO,F_FIN,CARGA_TABLAS,PUBLICACION,FORMATO,DESCRIPCION) VALUES ("&INFORMES!B81&",'"&INFORMES!C81&"','"&INFORMES!D81&"',TO_DATE('"&INFORMES!E81&"','yyyymmdd'),TO_DATE('"&INFORMES!F81&"','yyyymmdd'),'"&INFORMES!G81&"','"&INFORMES!H81&"','"&INFORMES!I81&"','"&INFORMES!J81&"');") -> INSERT INTO INYCEXT.INYC_CONF_INFORMES (COD_INFORME,DESC_INFORME,TABLA,F_INICIO,F_FIN,CARGA_TABLAS,PUBLICACION,FORMATO,DESCRIPCION) VALUES (33.2,'W-O - Gestiones Explotacion Detalle','INYC_GES_DETALLE',TO_DATE('20220501','yyyymmdd'),TO_DATE('20200101','yyyymmdd'),'1,2,3,4,5,6,7,8,9,10,11,12','1,2,3,4,5,6,7,8,9,10,11,12','excel','GEX'); | B80: =IF(INFORMES!J81="OBSOLETO","","INSERT INTO INYCEXT.INYC_CONF_INFORMES@tc_link (COD_INFORME,DESC_INFORME,TABLA,F_INICIO,F_FIN,CARGA_TABLAS,PUBLICACION,FORMATO,DESCRIPCION) VALUES ("&INFORMES!B81&",'"&INFORMES!C81&"','"&INFORMES!D81&"',TO_DATE('"&INFORMES!E81&"','yyyymmdd'),TO_DATE('"&INFORMES!F81&"','yyyymmdd'),'"&INFORMES!G81&"','"&INFORMES!H81&"','"&INFORMES!I81&"','"&INFORMES!J81&"');") -> INSERT INTO INYCEXT.INYC_CONF_INFORMES@tc_link (COD_INFORME,DESC_INFORME,TABLA,F_INICIO,F_FIN,CARGA_TABLAS,PUBLICACION,FORMATO,DESCRIPCION) VALUES (33.2,'W-O - Gestiones Explotacion Detalle','INYC_GES_DETALLE',TO_DATE('20220501','yyyymmdd'),TO_DATE('20200101','yyyymmdd'),'1,2,3,4,5,6,7,8,9,10,11,12','1,2,3,4,5,6,7,8,9,10,11,12','excel','GEX');
A81: =IF(INFORMES!J82="OBSOLETO","","INSERT INTO INYCEXT.INYC_CONF_INFORMES (COD_INFORME,DESC_INFORME,TABLA,F_INICIO,F_FIN,CARGA_TABLAS,PUBLICACION,FORMATO,DESCRIPCION) VALUES ("&INFORMES!B82&",'"&INFORMES!C82&"','"&INFORMES!D82&"',TO_DATE('"&INFORMES!E82&"','yyyymmdd'),TO_DATE('"&INFORMES!F82&"','yyyymmdd'),'"&INFORMES!G82&"','"&INFORMES!H82&"','"&INFORMES!I82&"','"&INFORMES!J82&"');") -> INSERT INTO INYCEXT.INYC_CONF_INFORMES (COD_INFORME,DESC_INFORME,TABLA,F_INICIO,F_FIN,CARGA_TABLAS,PUBLICACION,FORMATO,DESCRIPCION) VALUES (3.3,'3.3 Percepciones Agentes Eterna','INYC_PERC_E_AGENTES',TO_DATE('20170101','yyyymmdd'),TO_DATE('22000101','yyyymmdd'),'DIARIO','DIARIO','excel','PEAG_E');
A82: =IF(INFORMES!J83="OBSOLETO","","INSERT INTO INYCEXT.INYC_CONF_INFORMES (COD_INFORME,DESC_INFORME,TABLA,F_INICIO,F_FIN,CARGA_TABLAS,PUBLICACION,FORMATO,DESCRIPCION) VALUES ("&INFORMES!B83&",'"&INFORMES!C83&"','"&INFORMES!D83&"',TO_DATE('"&INFORMES!E83&"','yyyymmdd'),TO_DATE('"&INFORMES!F83&"','yyyymmdd'),'"&INFORMES!G83&"','"&INFORMES!H83&"','"&INFORMES!I83&"','"&INFORMES!J83&"');") -> INSERT INTO INYCEXT.INYC_CONF_INFORMES (COD_INFORME,DESC_INFORME,TABLA,F_INICIO,F_FIN,CARGA_TABLAS,PUBLICACION,FORMATO,DESCRIPCION) VALUES (3.4,'3.4 Percepciones Inspectores Eterna','INYC_PERC_E_INSPECTORES',TO_DATE('20220101','yyyymmdd'),TO_DATE('22000101','yyyymmdd'),'DIARIO','DIARIO','excel','PEIN_E');
A83: =IF(INFORMES!J84="OBSOLETO","","INSERT INTO INYCEXT.INYC_CONF_INFORMES (COD_INFORME,DESC_INFORME,TABLA,F_INICIO,F_FIN,CARGA_TABLAS,PUBLICACION,FORMATO,DESCRIPCION) VALUES ("&INFORMES!B84&",'"&INFORMES!C84&"','"&INFORMES!D84&"',TO_DATE('"&INFORMES!E84&"','yyyymmdd'),TO_DATE('"&INFORMES!F84&"','yyyymmdd'),'"&INFORMES!G84&"','"&INFORMES!H84&"','"&INFORMES!I84&"','"&INFORMES!J84&"');") -> INSERT INTO INYCEXT.INYC_CONF_INFORMES (COD_INFORME,DESC_INFORME,TABLA,F_INICIO,F_FIN,CARGA_TABLAS,PUBLICACION,FORMATO,DESCRIPCION) VALUES (117.1,'1.17 Produccion Inspectores Eterna','INYC_PROD_E_INSPECTORES',TO_DATE('20220101','yyyymmdd'),TO_DATE('22000101','yyyymmdd'),'DIARIO','DIARIO','excel','PRIN_E');
A84: =IF(INFORMES!J85="OBSOLETO","","INSERT INTO INYCEXT.INYC_CONF_INFORMES (COD_INFORME,DESC_INFORME,TABLA,F_INICIO,F_FIN,CARGA_TABLAS,PUBLICACION,FORMATO,DESCRIPCION) VALUES ("&INFORMES!B85&",'"&INFORMES!C85&"','"&INFORMES!D85&"',TO_DATE('"&INFORMES!E85&"','yyyymmdd'),TO_DATE('"&INFORMES!F85&"','yyyymmdd'),'"&INFORMES!G85&"','"&INFORMES!H85&"','"&INFORMES!I85&"','"&INFORMES!J85&"');") -> INSERT INTO INYCEXT.INYC_CONF_INFORMES (COD_INFORME,DESC_INFORME,TABLA,F_INICIO,F_FIN,CARGA_TABLAS,PUBLICACION,FORMATO,DESCRIPCION) VALUES (25.1,'W-O - Incentivos Inspectores Comerciales','INYC_RPI_RESUMEN',TO_DATE('20140101','yyyymmdd'),TO_DATE('22000101','yyyymmdd'),'DIARIO','DIARIO','pdf','PEPI');

Sheet REGLAS
A1: SPRINT | B1: COD_INFORME | C1: TABLA | D1: NOMBRE | F1: REGLA ANTIGUAS | G1: REGLA | H1: F_INICIO | I1: F_FIN | J1: DESCRIPCION | K1: EJEMPLO
A2: 1 | B2: 1.1 | C2: INYC_RPI_RESUMEN | D2: SM - Objetivo Anual RRTT | E2: =F2=G2 -> TRUE | F2: SM-O-RPP-Inspector-ObjetivoAnual-NumPolizas-001 | G2: =IF(ISERROR(VLOOKUP(F2,MODIFICACIONES_REALIZADAS!F:H,3,)),F2,VLOOKUP(F2,MODIFICACIONES_REALIZADAS!F:H,3,)) -> SM-O-RPP-Inspector-ObjetivoAnual-NumPolizas-001 | H2: 20140101 | I2: 22000101
A3: 1 | B3: 1.1 | C3: INYC_RPI_RESUMEN | D3: SM - Objetivo Anual Hogar | E3: =F3=G3 -> TRUE | F3: SM-O-RPP-Inspector-ObjetivoAnual-NumPolizas-002 | G3: =IF(ISERROR(VLOOKUP(F3,MODIFICACIONES_REALIZADAS!F:H,3,)),F3,VLOOKUP(F3,MODIFICACIONES_REALIZADAS!F:H,3,)) -> SM-O-RPP-Inspector-ObjetivoAnual-NumPolizas-002 | H3: 20140101 | I3: 22000101
A4: 1 | B4: 1.1 | C4: INYC_RPI_RESUMEN | D4: SM - Objetivo Anual RRPP | E4: =F4=G4 -> TRUE | F4: SM-O-RPP-Inspector-ObjetivoAnual-NumPolizas-906 | G4: =IF(ISERROR(VLOOKUP(F4,MODIFICACIONES_REALIZADAS!F:H,3,)),F4,VLOOKUP(F4,MODIFICACIONES_REALIZADAS!F:H,3,)) -> SM-O-RPP-Inspector-ObjetivoAnual-NumPolizas-906 | H4: 20140101 | I4: 22000101
A5: 1 | B5: 1.1 | C5: INYC_RPI_RESUMEN | D5: SM - Objetivo Anual Total Ramos | E5: =F5=G5 -> TRUE | F5: SM-O-RPP-Inspector-ObjetivoAnual-NumPolizas-998 | G5: =IF(ISERROR(VLOOKUP(F5,MODIFICACIONES_REALIZADAS!F:H,3,)),F5,VLOOKUP(F5,MODIFICACIONES_REALIZADAS!F:H,3,)) -> SM-O-RPP-Inspector-ObjetivoAnual-NumPolizas-998 | H5: 20140101 | I5: 22000101
A6: 1 | B6: 1.1 | C6: INYC_RPI_RESUMEN | D6: SM - Objetivo Único Anual PC | E6: =F6=G6 -> TRUE | F6: SM-O-RPP-Inspector-ObjetivoUnicoAnual-PrimaCorregida | G6: =IF(ISERROR(VLOOKUP(F6,MODIFICACIONES_REALIZADAS!F:H,3,)),F6,VLOOKUP(F6,MODIFICACIONES_REALIZADAS!F:H,3,)) -> SM-O-RPP-Inspector-ObjetivoUnicoAnual-PrimaCorregida | H6: 20140101 | I6: 22000101
A7: 1 | B7: 1.1 | C7: INYC_RPI_RESUMEN | D7: SM - Objetivo Trimestral Rappel1 RRTT | E7: =F7=G7 -> TRUE | F7: SM-O-RPP-Inspector-ObjetivoTrimestral-Rappel1-NumPolizas-001 | G7: =IF(ISERROR(VLOOKUP(F7,MODIFICACIONES_REALIZADAS!F:H,3,)),F7,VLOOKUP(F7,MODIFICACIONES_REALIZADAS!F:H,3,)) -> SM-O-RPP-Inspector-ObjetivoTrimestral-Rappel1-NumPolizas-001 | H7: 20140101 | I7: 22000101
A8: 1 | B8: 1.1 | C8: INYC_RPI_RESUMEN | D8: SM - Objetivo Trimestral Rappel1 Hogar | E8: =F8=G8 -> TRUE | F8: SM-O-RPP-Inspector-ObjetivoTrimestral-Rappel1-NumPolizas-002 | G8: =IF(ISERROR(VLOOKUP(F8,MODIFICACIONES_REALIZADAS!F:H,3,)),F8,VLOOKUP(F8,MODIFICACIONES_REALIZADAS!F:H,3,)) -> SM-O-RPP-Inspector-ObjetivoTrimestral-Rappel1-NumPolizas-002 | H8: 20140101 | I8: 22000101
A9: 1 | B9: 1.1 | C9: INYC_RPI_RESUMEN | D9: SM - Objetivo Trimestral Rappel1 RRPP | E9: =F9=G9 -> TRUE | F9: SM-O-RPP-Inspector-ObjetivoTrimestral-Rappel1-NumPolizas-906 | G9: =IF(ISERROR(VLOOKUP(F9,MODIFICACIONES_REALIZADAS!F:H,3,)),F9,VLOOKUP(F9,MODIFICACIONES_REALIZADAS!F:H,3,)) -> SM-O-RPP-Inspector-ObjetivoTrimestral-Rappel1-NumPolizas-906 | H9: 20140101 | I9: 22000101
A10: 1 | B10: 1.1 | C10: INYC_RPI_RESUMEN | D10: SM - Objetivo Trimestral Rappel1 Total Ramos | E10: =F10=G10 -> TRUE | F10: SM-O-RPP-Inspector-ObjetivoTrimestral-Rappel1-NumPolizas-998 | G10: =IF(ISERROR(VLOOKUP(F10,MODIFICACIONES_REALIZADAS!F:H,3,)),F10,VLOOKUP(F10,MODIFICACIONES_REALIZADAS!F:H,3,)) -> SM-O-RPP-Inspector-ObjetivoTrimestral-Rappel1-NumPolizas-998 | H10: 20140101 | I10: 22000101
A11: 1 | B11: 1.1 | C11: INYC_RPI_RESUMEN | D11: SM - Objetivo Trimestral Rappel2 Total Ramos | E11: =F11=G11 -> TRUE | F11: SM-O-RPP-Inspector-ObjetivoTrimestral-Rappel2-NumPolizas-998 | G11: =IF(ISERROR(VLOOKUP(F11,MODIFICACIONES_REALIZADAS!F:H,3,)),F11,VLOOKUP(F11,MODIFICACIONES_REALIZADAS!F:H,3,)) -> SM-O-RPP-Inspector-ObjetivoTrimestral-Rappel2-NumPolizas-998 | H11: 20140101 | I11: 22000101
A12: 1 | B12: 1.1 | C12: INYC_RPI_RESUMEN | D12: SM - Importe Reg. Anual Rappel1 Mes1 | E12: =F12=G12 -> TRUE | F12: SM-RPP-Inspector-ImportesRegularizacionAnual-Rappel1-Mes1 | G12: =IF(ISERROR(VLOOKUP(F12,MODIFICACIONES_REALIZADAS!F:H,3,)),F12,VLOOKUP(F12,MODIFICACIONES_REALIZADAS!F:H,3,)) -> SM-RPP-Inspector-ImportesRegularizacionAnual-Rappel1-Mes1 | H12: 20140101 | I12: 22000101
A13: 1 | B13: 1.1 | C13: INYC_RPI_RESUMEN | D13: SM - Importe Reg. Anual Rappel1 Mes10 | E13: =F13=G13 -> TRUE | F13: SM-RPP-Inspector-ImportesRegularizacionAnual-Rappel1-Mes10 | G13: =IF(ISERROR(VLOOKUP(F13,MODIFICACIONES_REALIZADAS!F:H,3,)),F13,VLOOKUP(F13,MODIFICACIONES_REALIZADAS!F:H,3,)) -> SM-RPP-Inspector-ImportesRegularizacionAnual-Rappel1-Mes10 | H13: 20140101 | I13: 22000101
... A24: 1 | B24: 1.1 | C24: INYC_RPI_RESUMEN | D24: SM - Pago Reg. Anual Final | E24: =F24=G24 -> TRUE | F24: SM-RPP-Inspector-PagoRegularizacion-Anual-Final | G24: =IF(ISERROR(VLOOKUP(F24,MODIFICACIONES_REALIZADAS!F:H,3,)),F24,VLOOKUP(F24,MODIFICACIONES_REALIZADAS!F:H,3,)) -> SM-RPP-Inspector-PagoRegularizacion-Anual-Final | H24: 20140101 | I24: 22000101
A25: 1 | B25: 1.1 | C25: INYC_RPI_RESUMEN | D25: PM - Numero Pólizas RRTT | E25: =F25=G25 -> FALSE | F25: PM-GEN-NumeroPolizas-001 | G25: =IF(ISERROR(VLOOKUP(F25,MODIFICACIONES_REALIZADAS!F:H,3,)),F25,VLOOKUP(F25,MODIFICACIONES_REALIZADAS!F:H,3,)) -> PM-O-GEN-Inspector-NumeroPolizas-001 | H25: 20140101 | I25: 20180101 | J25: Version 20180126
A26: 1 | B26: 1.1 | C26: INYC_RPI_RESUMEN | D26: PM - Numero Pólizas Hogar | E26: =F26=G26 -> FALSE | F26: PM-GEN-NumeroPolizas-002 | G26: =IF(ISERROR(VLOOKUP(F26,MODIFICACIONES_REALIZADAS!F:H,3,)),F26,VLOOKUP(F26,MODIFICACIONES_REALIZADAS!F:H,3,)) -> PM-O-GEN-Inspector-NumeroPolizas-002 | H26: 20140101 | I26: 20180101 | J26: Version 20180126
A27: 1 | B27: 1.1 | C27: INYC_RPI_RESUMEN | D27: PM - Numero Pólizas RRPP | E27: =F27=G27 -> FALSE | F27: PM-GEN-NumeroPolizas-906 | G27: =IF(ISERROR(VLOOKUP(F27,MODIFICACIONES_REALIZADAS!F:H,3,)),F27,VLOOKUP(F27,MODIFICACIONES_REALIZADAS!F:H,3,)) -> PM-O-GEN-Inspector-NumeroPolizas-906 | H27: 20140101 | I27: 20180101 | J27: Version 20180126
A28: 1 | B28: 1.1 | C28: INYC_RPI_RESUMEN | D28: PM - Numero Pólizas Total Ramos | E28: =F28=G28 -> FALSE | F28: PM-GEN-NumeroPolizas-998 | G28: =IF(ISERROR(VLOOKUP(F28,MODIFICACIONES_REALIZADAS!F:H,3,)),F28,VLOOKUP(F28,MODIFICACIONES_REALIZADAS!F:H,3,)) -> PM-O-GEN-Inspector-NumeroPolizas-998 | H28: 20140101 | I28: 20180101 | J28: Version 20180126
A29: 1 | B29: 1.1 | C29: INYC_RPI_RESUMEN | D29: PM - Numero Pólizas Corregidas RRTT | E29: =F29=G29 -> TRUE | F29: PM-O-GEN-Inspector-NumeroPolizasCorregidas-001 | G29: =IF(ISERROR(VLOOKUP(F29,MODIFICACIONES_REALIZADAS!F:H,3,)),F29,VLOOKUP(F29,MODIFICACIONES_REALIZADAS!F:H,3,)) -> PM-O-GEN-Inspector-NumeroPolizasCorregidas-001 | H29: 20180101 | I29: 22000101 | J29: Version 20180126
A30: 1 | B30: 1.1 | C30: INYC_RPI_RESUMEN | D30: PM - Numero Pólizas Corregidas Hogar | E30: =F30=G30 -> TRUE | F30: PM-O-GEN-Inspector-NumeroPolizasCorregidas-002 | G30: =IF(ISERROR(VLOOKUP(F30,MODIFICACIONES_REALIZADAS!F:H,3,)),F30,VLOOKUP(F30,MODIFICACIONES_REALIZADAS!F:H,3,)) -> PM-O-GEN-Inspector-NumeroPolizasCorregidas-002 | H30: 20180101 | I30: 22000101 | J30: Version 20180126
A31: 1 | B31: 1.1 | C31: INYC_RPI_RESUMEN | D31: PM - Numero Pólizas Corregidas RRPP | E31: =F31=G31 -> TRUE | F31: PM-O-GEN-Inspector-NumeroPolizasCorregidas-906 | G31: =IF(ISERROR(VLOOKUP(F31,MODIFICACIONES_REALIZADAS!F:H,3,)),F31,VLOOKUP(F31,MODIFICACIONES_REALIZADAS!F:H,3,)) -> PM-O-GEN-Inspector-NumeroPolizasCorregidas-906 | H31: 20180101 | I31: 22000101 | J31: Version 20180126
A32: 1 | B32: 1.1 | C32: INYC_RPI_RESUMEN | D32: PM - Prima Corregida Total Ramos | E32: =F32=G32 -> FALSE | F32: PM-RPP-Inspector-PrimaCorregida | G32: =IF(ISERROR(VLOOKUP(F32,MODIFICACIONES_REALIZADAS!F:H,3,)),F32,VLOOKUP(F32,MODIFICACIONES_REALIZADAS!F:H,3,)) -> PM-O-GEN-Inspector-PrimaCorregida-998 | H32: 20140101 | I32: 22000101
A33: 1 | B33: 1.1 | C33: INYC_RPI_RESUMEN | D33: PM - Numero Pólizas Corregidas Total Ramos | E33: =F33=G33 -> TRUE | F33: PM-O-GEN-Inspector-NumeroPolizasCorregidas-998 | G33: =IF(ISERROR(VLOOKUP(F33,MODIFICACIONES_REALIZADAS!F:H,3,)),F33,VLOOKUP(F33,MODIFICACIONES_REALIZADAS!F:H,3,)) -> PM-O-GEN-Inspector-NumeroPolizasCorregidas-998 | H33: 20180101 | I33: 22000101 | J33: Version 20180119
A34: 1 | B34: 1.1 | C34: INYC_RPI_RESUMEN | D34: PM - Nº Asegurados Inspector | E34: =F34=G34 -> TRUE | F34: PM-O-GEN-Agente-NumAsegurados | G34: =IF(ISERROR(VLOOKUP(F34,MODIFICACIONES_REALIZADAS!F:H,3,)),F34,VLOOKUP(F34,MODIFICACIONES_REALIZADAS!F:H,3,)) -> PM-O-GEN-Agente-NumAsegurados | H34: 20180101 | I34: 22000101 | J34: Version 20180119
A35: 1 | B35: 1.1 | C35: INYC_RPI_RESUMEN | D35: PM - Numero Pólizas RRTT Agentes | E35: =F35=G35 -> FALSE | F35: PM-GEN-NumeroPolizas-001-Agentes | G35: =IF(ISERROR(VLOOKUP(F35,MODIFICACIONES_REALIZADAS!F:H,3,)),F35,VLOOKUP(F35,MODIFICACIONES_REALIZADAS!F:H,3,)) -> PM-O-GEN-Inspector-NumeroPolizas-001-Agentes | H35: 20140101 | I35: 20180101 | J35: Version 20180126
A36: 1 | B36: 1.1 | C36: INYC_RPI_RESUMEN | D36: PM - Numero Pólizas Hogar Agentes | E36: =F36=G36 -> FALSE | F36: PM-GEN-NumeroPolizas-002-Agentes | G36: =IF(ISERROR(VLOOKUP(F36,MODIFICACIONES_REALIZADAS!F:H,3,)),F36,VLOOKUP(F36,MODIFICACIONES_REALIZADAS!F:H,3,)) -> PM-O-GEN-Inspector-NumeroPolizas-002-Agentes | H36: 20140101 | I36: 20180101 | J36: Version 20180126
A37: 1 | B37: 1.1 | C37: INYC_RPI_RESUMEN | D37: PM - Numero Pólizas RRPP Agentes | E37: =F37=G37 -> FALSE | F37: PM-GEN-NumeroPolizas-906-Agentes | G37: =IF(ISERROR(VLOOKUP(F37,MODIFICACIONES_REALIZADAS!F:H,3,)),F37,VLOOKUP(F37,MODIFICACIONES_REALIZADAS!F:H,3,)) -> PM-O-GEN-Inspector-NumeroPolizas-906-Agentes | H37: 20140101 | I37: 20180101 | J37: Version 20180126
A38: 1 | B38: 1.1 | C38: INYC_RPI_RESUMEN | D38: PM - Numero Pólizas Total Ramos Agentes | E38: =F38=G38 -> FALSE | F38: PM-GEN-NumeroPolizas-998-Agentes | G38: =IF(ISERROR(VLOOKUP(F38,MODIFICACIONES_REALIZADAS!F:H,3,)),F38,VLOOKUP(F38,MODIFICACIONES_REALIZADAS!F:H,3,)) -> PM-O-GEN-Inspector-NumeroPolizas-998-Agentes | H38: 20140101 | I38: 20180101 | J38: Version 20180126
A39: 1 | B39: 1.1 | C39: INYC_RPI_RESUMEN | D39: PM - Numero Pólizas Corregidas RRTT Agentes | E39: =F39=G39 -> TRUE | F39: PM-O-GEN-Inspector-NumeroPolizasCorregidas-001-Agentes | G39: =IF(ISERROR(VLOOKUP(F39,MODIFICACIONES_REALIZADAS!F:H,3,)),F39,VLOOKUP(F39,MODIFICACIONES_REALIZADAS!F:H,3,)) -> PM-O-GEN-Inspector-NumeroPolizasCorregidas-001-Agentes | H39: 20180101 | I39: 22000101 | J39: Version 20180126
A40: 1 | B40: 1.1 | C40: INYC_RPI_RESUMEN | D40: PM - Numero Pólizas Corregidas Hogar Agentes | E40: =F40=G40 -> TRUE | F40: PM-O-GEN-Inspector-NumeroPolizasCorregidas-002-Agentes | G40: =IF(ISERROR(VLOOKUP(F40,MODIFICACIONES_REALIZADAS!F:H,3,)),F40,VLOOKUP(F40,MODIFICACIONES_REALIZADAS!F:H,3,)) -> PM-O-GEN-Inspector-NumeroPolizasCorregidas-002-Agentes | H40: 20180101 | I40: 22000101 | J40: Version 20180126
A41: 1 | B41: 1.1 | C41: INYC_RPI_RESUMEN | D41: PM - Numero Pólizas Corregidas RRPP Agentes | E41: =F41=G41 -> TRUE | F41: PM-O-GEN-Inspector-NumeroPolizasCorregidas-906-Agentes | G41: =IF(ISERROR(VLOOKUP(F41,MODIFICACIONES_REALIZADAS!F:H,3,)),F41,VLOOKUP(F41,MODIFICACIONES_REALIZADAS!F:H,3,)) -> PM-O-GEN-Inspector-NumeroPolizasCorregidas-906-Agentes | H41: 20180101 | I41: 22000101 | J41: Version 20180126
A42: 1 | B42: 1.1 | C42: INYC_RPI_RESUMEN | D42: PM - Prima Corregida Total Ramos Agentes | E42: =F42=G42 -> FALSE | F42: PM-RPP-Inspector-PrimaCorregida-Agentes | G42: =IF(ISERROR(VLOOKUP(F42,MODIFICACIONES_REALIZADAS!F:H,3,)),F42,VLOOKUP(F42,MODIFICACIONES_REALIZADAS!F:H,3,)) -> PM-O-GEN-Inspector-PrimaCorregida-998-Agentes | H42: 20140101 | I42: 22000101
A43: 1 | B43: 1.1 | C43: INYC_RPI_RESUMEN | D43: PM - Numero Pólizas Corregidas Total Ramos | E43: =F43=G43 -> TRUE | F43: PM-O-GEN-Inspector-NumeroPolizasCorregidas-998-Agentes | G43: =IF(ISERROR(VLOOKUP(F43,MODIFICACIONES_REALIZADAS!F:H,3,)),F43,VLOOKUP(F43,MODIFICACIONES_REALIZADAS!F:H,3,)) -> PM-O-GEN-Inspector-NumeroPolizasCorregidas-998-Agentes | H43: 20180101 | I43: 22000101 | J43: Version 20180119
A44: 1 | B44: 1.1 | C44: INYC_RPI_RESUMEN | D44: PM - Nº Asegurados Inspector Agentes | E44: =F44=G44 -> TRUE | F44: PM-O-GEN-Inspector-NumAsegurados-Agentes | G44: =IF(ISERROR(VLOOKUP(F44,MODIFICACIONES_REALIZADAS!F:H,3,)),F44,VLOOKUP(F44,MODIFICACIONES_REALIZADAS!F:H,3,)) -> PM-O-GEN-Inspector-NumAsegurados-Agentes | H44: 20180101 | I44: 22000101 | J44: Version 20180117
A45: 1 | B45: 1.1 | C45: INYC_RPI_RESUMEN | D45: SM - Nº Pólizas Inspector RRTT Mensual | E45: =F45=G45 -> FALSE | F45: SM-RPP-Inspector-NumeroPolizas-001-TotalMes | G45: =IF(ISERROR(VLOOKUP(F45,MODIFICACIONES_REALIZADAS!F:H,3,)),F45,VLOOKUP(F45,MODIFICACIONES_REALIZADAS!F:H,3,)) -> SM-O-GEN-Inspector-NumeroPolizas-001-TotalMes | H45: 20140101 | I45: 20180101 | J45: Version 20180126
A46: 1 | B46: 1.1 | C46: INYC_RPI_RESUMEN | D46: SM - Nº Pólizas Inspector Hogar Mensual | E46: =F46=G46 -> FALSE | F46: SM-RPP-Inspector-NumeroPolizas-002-TotalMes | G46: =IF(ISERROR(VLOOKUP(F46,MODIFICACIONES_REALIZADAS!F:H,3,)),F46,VLOOKUP(F46,MODIFICACIONES_REALIZADAS!F:H,3,)) -> SM-O-GEN-Inspector-NumeroPolizas-002-TotalMes | H46: 20140101 | I46: 20180101 | J46: Version 20180126
A47: 1 | B47: 1.1 | C47: INYC_RPI_RESUMEN | D47: SM - Nº Pólizas Inspector RRPP (excl PU y conv/colec) Mensual | E47: =F47=G47 -> FALSE | F47: SM-RPP-Inspector-NumeroPolizas-906-TotalMes | G47: =IF(ISERROR(VLOOKUP(F47,MODIFICACIONES_REALIZADAS!F:H,3,)),F47,VLOOKUP(F47,MODIFICACIONES_REALIZADAS!F:H,3,)) -> SM-O-GEN-Inspector-NumeroPolizas-906-TotalMes | H47: 20140101 | I47: 20180101 | J47: Version 20180126
A48: 1 | B48: 1.1 | C48: INYC_RPI_RESUMEN | D48: SM - Nº Pólizas Inspector Total Productos Mensual | E48: =F48=G48 -> FALSE | F48: SM-RPP-Inspector-NumeroPolizas-998-TotalMes | G48: =IF(ISERROR(VLOOKUP(F48,MODIFICACIONES_REALIZADAS!F:H,3,)),F48,VLOOKUP(F48,MODIFICACIONES_REALIZADAS!F:H,3,)) -> SM-O-GEN-Inspector-NumeroPolizas-998-TotalMes | H48: 20140101 | I48: 20180101 | J48: Version 20180126
A49: 1 | B49: 1.1 | C49: INYC_RPI_RESUMEN | D49: SM - Nº Pólizas Corregidas Inspector RRTT Mensual | E49: =F49=G49 -> TRUE | F49: SM-O-GEN-Inspector-NumeroPolizasCorregidas-001-TotalMes | G49: =IF(ISERROR(VLOOKUP(F49,MODIFICACIONES_REALIZADAS!F:H,3,)),F49,VLOOKUP(F49,MODIFICACIONES_REALIZADAS!F:H,3,)) -> SM-O-GEN-Inspector-NumeroPolizasCorregidas-001-TotalMes | H49: 20180101 | I49: 22000101 | J49: Version 20180126
A50: 1 | B50: 1.1 | C50: INYC_RPI_RESUMEN | D50: SM - Nº Pólizas Corregidas Inspector Hogar Mensual | E50: =F50=G50 -> TRUE | F50: SM-O-GEN-Inspector-NumeroPolizasCorregidas-002-TotalMes | G50: =IF(ISERROR(VLOOKUP(F50,MODIFICACIONES_REALIZADAS!F:H,3,)),F50,VLOOKUP(F50,MODIFICACIONES_REALIZADAS!F:H,3,)) -> SM-O-GEN-Inspector-NumeroPolizasCorregidas-002-TotalMes | H50: 20180101 | I50: 22000101 | J50: Version 20180126
...

Sheet MODIFICACIONES_REALIZADAS
A1: id | B1: LINEA | C1: TIPO | E1: REGLA VIEJA | F1: NOMBRE SALIDA REGLA VIEJA | G1: REGLA NUEVA | H1: NOMBRE SALIDA REGLA NUEVA | I1: ACCION
A2: 1 | B2: 1 | C2: Inspector | D2: DC | E2: DC-GEN-NumeroPolizas-001 | F2: DC-GEN-NumeroPolizas-001 | G2: DC-O-GEN-Inspector-NumeroPolizas-001 | H2: DC-O-GEN-Inspector-NumeroPolizas-001 | I2: CAMBIO NOMBRE
A3: 2 | B3: 2 | C3: Inspector | D3: DC | E3: DC-GEN-NumeroPolizas-002 | F3: DC-GEN-NumeroPolizas-002 | G3: DC-O-GEN-Inspector-NumeroPolizas-002 | H3: DC-O-GEN-Inspector-NumeroPolizas-002 | I3: CAMBIO NOMBRE
A4: 3 | B4: 1 | C4: Inspector | D4: IC | E4: IC-GEN-NumeroPolizas-001 | F4: IC-GEN-NumeroPolizas-001 | G4: IC-O-GEN-Inspector-NumeroPolizas-001 | H4: IC-O-GEN-Inspector-NumeroPolizas-001 | I4: CAMBIO NOMBRE
A5: 4 | B5: 2 | C5: Inspector | D5: IC | E5: IC-GEN-NumeroPolizas-002 | F5: IC-GEN-NumeroPolizas-002 | G5: IC-O-GEN-Inspector-NumeroPolizas-002 | H5: IC-O-GEN-Inspector-NumeroPolizas-002 | I5: CAMBIO NOMBRE
A6: 5 | B6: 3 | C6: Inspector | D6: DC | G6: DC-O-GEN-Inspector-NumeroPolizas-003 | H6: DC-O-GEN-Inspector-NumeroPolizas-003 | I6: NUEVA
A7: 6 | B7: 4 | C7: Inspector | D7: DC | G7: DC-O-GEN-Inspector-NumeroPolizas-004 | H7: DC-O-GEN-Inspector-NumeroPolizas-004 | I7: NUEVA
A8: 7 | B8: 5 | C8: Inspector | D8: DC | G8: DC-O-GEN-Inspector-NumeroPolizas-005 | H8: DC-O-GEN-Inspector-NumeroPolizas-005 | I8: NUEVA
A9: 8 | B9: 6 | C9: Inspector | D9: DC | G9: DC-O-GEN-Inspector-NumeroPolizas-006 | H9: DC-O-GEN-Inspector-NumeroPolizas-006 | I9: NUEVA
A10: 9 | B10: 7 | C10: Inspector | D10: DC | G10: DC-O-GEN-Inspector-NumeroPolizas-007 | H10: DC-O-GEN-Inspector-NumeroPolizas-007 | I10: NUEVA
A11: 10 | B11: 3 | C11: Inspector | D11: IC | G11: IC-O-GEN-Inspector-NumeroPolizas-003 | H11: IC-O-GEN-Inspector-NumeroPolizas-003 | I11: NUEVA
A12: 11 | B12: 4 | C12: Inspector | D12: IC | G12: IC-O-GEN-Inspector-NumeroPolizas-004 | H12: IC-O-GEN-Inspector-NumeroPolizas-004 | I12: NUEVA
A13: 12 | B13: 5 | C13: Inspector | D13: IC | G13: IC-O-GEN-Inspector-NumeroPolizas-005 | H13: IC-O-GEN-Inspector-NumeroPolizas-005 | I13: NUEVA
A14: 13 | B14: 6 | C14: Inspector | D14: IC | G14: IC-O-GEN-Inspector-NumeroPolizas-006 | H14: IC-O-GEN-Inspector-NumeroPolizas-006 | I14: NUEVA
A15: 14 | B15: 7 | C15: Inspector | D15: IC | G15: IC-O-GEN-Inspector-NumeroPolizas-007 | H15: IC-O-GEN-Inspector-NumeroPolizas-007 | I15: NUEVA
A16: 15 | B16: 9 | C16: Inspector | D16: DC | G16: DC-O-GEN-Inspector-NumeroPolizas-009 | H16: DC-O-GEN-Inspector-NumeroPolizas-009 | I16: NUEVA
A17: 16 | B17: 9 | C17: Inspector | D17: IC | G17: IC-O-GEN-Inspector-NumeroPolizas-009 | H17: IC-O-GEN-Inspector-NumeroPolizas-009 | I17: NUEVA
A18: 17 | B18: 997 | C18: Inspector | D18: DC | E18: DC-O-GEN-Inspector-NumeroPolizas-997 | F18: DC-O-GEN-Inspector-NumeroPolizas-997 | G18: DC-O-GEN-Inspector-NumeroPolizas-998 y GB1 | H18: DC-O-GEN-Inspector-NumeroPolizas-998 | I18: ELIMINAR
A19: 18 | B19: 997 | C19: Inspector | D19: IC | E19: IC-O-GEN-Inspector-NumeroPolizas-997 | F19: IC-O-GEN-Inspector-NumeroPolizas-997 | G19: IC-O-GEN-Inspector-NumeroPolizas-998 y GB1 | H19: IC-O-GEN-Inspector-NumeroPolizas-998 | I19: ELIMINAR
A20: 19 | B20: 998 | C20: Inspector | D20: DC | E20: DC-GEN-NumeroPolizas-998 | F20: DC-GEN-NumeroPolizas-998 | G20: DC-O-GEN-Inspector-NumeroPolizas-998 | H20: DC-O-GEN-Inspector-NumeroPolizas-998 | I20: CAMBIO NOMBRE
A21: 20 | B21: 998 | C21: Inspector | D21: IC | E21: IC-GEN-NumeroPolizas-998 | F21: IC-GEN-NumeroPolizas-998 | G21: IC-O-GEN-Inspector-NumeroPolizas-998 | H21: IC-O-GEN-Inspector-NumeroPolizas-998 | I21: CAMBIO NOMBRE
A22: 21 | B22: 1 | C22: Inspector | D22: PM | E22: PM-GEN-NumeroPolizas-001-Agentes | F22: PM-GEN-NumeroPolizas-001-Agentes | G22: PM-O-GEN-Inspector-NumeroPolizas-001-Agentes | H22: PM-O-GEN-Inspector-NumeroPolizas-001-Agentes | I22: CAMBIO NOMBRE
A23: 22 | B23: 1 | C23: Inspector | D23: PM | E23: PM-GEN-NumeroPolizas-001 | F23: PM-GEN-NumeroPolizas-001 | G23: PM-O-GEN-Inspector-NumeroPolizas-001 | H23: PM-O-GEN-Inspector-NumeroPolizas-001 | I23: CAMBIO NOMBRE
A24: 23 | B24: 2 | C24: Inspector | D24: PM | E24: PM-GEN-NumeroPolizas-002-Agentes | F24: PM-GEN-NumeroPolizas-002-Agentes | G24: PM-O-GEN-Inspector-NumeroPolizas-002-Agentes | H24: PM-O-GEN-Inspector-NumeroPolizas-002-Agentes | I24: CAMBIO NOMBRE
A25: 24 | B25: 2 | C25: Inspector | D25: PM | E25: PM-GEN-NumeroPolizas-002 | F25: PM-GEN-NumeroPolizas-002 | G25: PM-O-GEN-Inspector-NumeroPolizas-002 | H25: PM-O-GEN-Inspector-NumeroPolizas-002 | I25: CAMBIO NOMBRE
A26: 25 | B26: 3 | C26: Inspector | D26: PM | G26: PM-O-GEN-Inspector-NumeroPolizas-003-Agentes | H26: PM-O-GEN-Inspector-NumeroPolizas-003-Agentes | I26: NUEVA
A27: 26 | B27: 3 | C27: Inspector | D27: PM | G27: PM-O-GEN-Inspector-NumeroPolizas-003 | H27: PM-O-GEN-Inspector-NumeroPolizas-003 | I27: NUEVA
A28: 27 | B28: 4 | C28: Inspector | D28: PM | G28: PM-O-GEN-Inspector-NumeroPolizas-004-Agentes | H28: PM-O-GEN-Inspector-NumeroPolizas-004-Agentes | I28: NUEVA
A29: 28 | B29: 4 | C29: Inspector | D29: PM | G29: PM-O-GEN-Inspector-NumeroPolizas-004 | H29: PM-O-GEN-Inspector-NumeroPolizas-004 | I29: NUEVA
A30: 29 | B30: 5 | C30: Inspector | D30: PM | G30: PM-O-GEN-Inspector-NumeroPolizas-006-Agentes | H30: PM-O-GEN-Inspector-NumeroPolizas-006-Agentes | I30: NUEVA
A31: 30 | B31: 5 | C31: Inspector | D31: PM | G31: PM-O-GEN-Inspector-NumeroPolizas-005 | H31: PM-O-GEN-Inspector-NumeroPolizas-005 | I31: NUEVA
A32: 31 | B32: 6 | C32: Inspector | D32: PM | G32: PM-O-GEN-Inspector-NumeroPolizas-006-Agentes | H32: PM-O-GEN-Inspector-NumeroPolizas-006-Agentes | I32: NUEVA
A33: 32 | B33: 6 | C33: Inspector | D33: PM | G33: PM-O-GEN-Inspector-NumeroPolizas-006 | H33: PM-O-GEN-Inspector-NumeroPolizas-006 | I33: NUEVA
A34: 33 | B34: 7 | C34: Inspector | D34: PM | G34: PM-O-GEN-Inspector-NumeroPolizas-007-Agentes | H34: PM-O-GEN-Inspector-NumeroPolizas-007-Agentes | I34: NUEVA
A35: 34 | B35: 7 | C35: Inspector | D35: PM | G35: PM-O-GEN-Inspector-NumeroPolizas-007 | H35: PM-O-GEN-Inspector-NumeroPolizas-007 | I35: NUEVA
A36: 35 | B36: 9 | C36: Inspector | D36: PM | G36: PM-O-GEN-Inspector-NumeroPolizas-009-Agentes | H36: PM-O-GEN-Inspector-NumeroPolizas-009-Agentes | I36: NUEVA
A37: 36 | B37: 9 | C37: Inspector | D37: PM | G37: PM-O-GEN-Inspector-NumeroPolizas-009 | H37: PM-O-GEN-Inspector-NumeroPolizas-009 | I37: NUEVA
A38: 37 | B38: 998 | C38: Inspector | D38: PM | E38: PM-GEN-NumeroPolizas-998-Agentes | F38: PM-GEN-NumeroPolizas-998-Agentes | G38: PM-O-GEN-Inspector-NumeroPolizas-998-Agentes | H38: PM-O-GEN-Inspector-NumeroPolizas-998-Agentes | I38: CAMBIO NOMBRE
A39: 38 | B39: 998 | C39: Inspector | D39: PM | E39: PM-GEN-NumeroPolizas-998 | F39: PM-GEN-NumeroPolizas-998 | G39: PM-O-GEN-Inspector-NumeroPolizas-998 | H39: PM-O-GEN-Inspector-NumeroPolizas-998 | I39: CAMBIO NOMBRE
A40: 39 | B40: 1 | C40: Inspector | D40: SM | E40: SM-RPP-Inspector-NumeroPolizas-001-TotalMes | F40: SM-RPP-Inspector-NumeroPolizas-001-Propia | G40: SM-O-GEN-Inspector-NumeroPolizas-001-TotalMes | H40: SM-O-GEN-Inspector-NumeroPolizas-001-Propia | I40: CAMBIO NOMBRE
...

Sheet INSERT REGLAS
A1: =IF(REGLAS!J2="OBSOLETO","","INSERT INTO INYCEXT.INYC_CONF_INF_REGLAS (COD_INFORME,TABLA,NOMBRE,REGLA,F_INICIO,F_FIN,DESCRIPCION) VALUES ("&REGLAS!B2&",'"&REGLAS!C2&"','"&REGLAS!D2&"','"&REGLAS!G2&"',TO_DATE('"&REGLAS!H2&"','yyyymmdd'),TO_DATE('"&REGLAS!I2&"','yyyymmdd'),'"&REGLAS!J2&"');") -> INSERT INTO INYCEXT.INYC_CONF_INF_REGLAS (COD_INFORME,TABLA,NOMBRE,REGLA,F_INICIO,F_FIN,DESCRIPCION) VALUES (1.1,'INYC_RPI_RESUMEN','SM - Objetivo Anual RRTT','SM-O-RPP-Inspector-ObjetivoAnual-NumPolizas-001',TO_DATE('20140101','yyyymmdd'),TO_DATE('22000101','yyyymmdd'),''); | B1: =IF(REGLAS!J2="OBSOLETO","","INSERT INTO INYCEXT.INYC_CONF_INF_REGLAS@tc_link (COD_INFORME,TABLA,NOMBRE,REGLA,F_INICIO,F_FIN,DESCRIPCION) VALUES ("&REGLAS!B2&",'"&REGLAS!C2&"','"&REGLAS!D2&"','"&REGLAS!G2&"',TO_DATE('"&REGLAS!H2&"','yyyymmdd'),TO_DATE('"&REGLAS!I2&"','yyyymmdd'),'"&REGLAS!J2&"');") -> INSERT INTO INYCEXT.INYC_CONF_INF_REGLAS@tc_link (COD_INFORME,TABLA,NOMBRE,REGLA,F_INICIO,F_FIN,DESCRIPCION) VALUES (1.1,'INYC_RPI_RESUMEN','SM - Objetivo Anual RRTT','SM-O-RPP-Inspector-ObjetivoAnual-NumPolizas-001',TO_DATE('20140101','yyyymmdd'),TO_DATE('22000101','yyyymmdd'),'');
A2: =IF(REGLAS!J3="OBSOLETO","","INSERT INTO INYCEXT.INYC_CONF_INF_REGLAS (COD_INFORME,TABLA,NOMBRE,REGLA,F_INICIO,F_FIN,DESCRIPCION) VALUES ("&REGLAS!B3&",'"&REGLAS!C3&"','"&REGLAS!D3&"','"&REGLAS!G3&"',TO_DATE('"&REGLAS!H3&"','yyyymmdd'),TO_DATE('"&REGLAS!I3&"','yyyymmdd'),'"&REGLAS!J3&"');") -> INSERT INTO INYCEXT.INYC_CONF_INF_REGLAS (COD_INFORME,TABLA,NOMBRE,REGLA,F_INICIO,F_FIN,DESCRIPCION) VALUES (1.1,'INYC_RPI_RESUMEN','SM - Objetivo Anual Hogar','SM-O-RPP-Inspector-ObjetivoAnual-NumPolizas-002',TO_DATE('20140101','yyyymmdd'),TO_DATE('22000101','yyyymmdd'),''); | B2: =IF(REGLAS!J3="OBSOLETO","","INSERT INTO INYCEXT.INYC_CONF_INF_REGLAS@tc_link (COD_INFORME,TABLA,NOMBRE,REGLA,F_INICIO,F_FIN,DESCRIPCION) VALUES ("&REGLAS!B3&",'"&REGLAS!C3&"','"&REGLAS!D3&"','"&REGLAS!G3&"',TO_DATE('"&REGLAS!H3&"','yyyymmdd'),TO_DATE('"&REGLAS!I3&"','yyyymmdd'),'"&REGLAS!J3&"');") -> INSERT INTO INYCEXT.INYC_CONF_INF_REGLAS@tc_link (COD_INFORME,TABLA,NOMBRE,REGLA,F_INICIO,F_FIN,DESCRIPCION) VALUES (1.1,'INYC_RPI_RESUMEN','SM - Objetivo Anual Hogar','SM-O-RPP-Inspector-ObjetivoAnual-NumPolizas-002',TO_DATE('20140101','yyyymmdd'),TO_DATE('22000101','yyyymmdd'),'');
A3: =IF(REGLAS!J4="OBSOLETO","","INSERT INTO INYCEXT.INYC_CONF_INF_REGLAS (COD_INFORME,TABLA,NOMBRE,REGLA,F_INICIO,F_FIN,DESCRIPCION) VALUES ("&REGLAS!B4&",'"&REGLAS!C4&"','"&REGLAS!D4&"','"&REGLAS!G4&"',TO_DATE('"&REGLAS!H4&"','yyyymmdd'),TO_DATE('"&REGLAS!I4&"','yyyymmdd'),'"&REGLAS!J4&"');") -> INSERT INTO INYCEXT.INYC_CONF_INF_REGLAS (COD_INFORME,TABLA,NOMBRE,REGLA,F_INICIO,F_FIN,DESCRIPCION) VALUES (1.1,'INYC_RPI_RESUMEN','SM - Objetivo Anual RRPP','SM-O-RPP-Inspector-ObjetivoAnual-NumPolizas-906',TO_DATE('20140101','yyyymmdd'),TO_DATE('22000101','yyyymmdd'),''); | B3: =IF(REGLAS!J4="OBSOLETO","","INSERT INTO INYCEXT.INYC_CONF_INF_REGLAS@tc_link (COD_INFORME,TABLA,NOMBRE,REGLA,F_INICIO,F_FIN,DESCRIPCION) VALUES ("&REGLAS!B4&",'"&REGLAS!C4&"','"&REGLAS!D4&"','"&REGLAS!G4&"',TO_DATE('"&REGLAS!H4&"','yyyymmdd'),TO_DATE('"&REGLAS!I4&"','yyyymmdd'),'"&REGLAS!J4&"');") -> INSERT INTO INYCEXT.INYC_CONF_INF_REGLAS@tc_link (COD_INFORME,TABLA,NOMBRE,REGLA,F_INICIO,F_FIN,DESCRIPCION) VALUES (1.1,'INYC_RPI_RESUMEN','SM - Objetivo Anual RRPP','SM-O-RPP-Inspector-ObjetivoAnual-NumPolizas-906',TO_DATE('20140101','yyyymmdd'),TO_DATE('22000101','yyyymmdd'),'');
A4: =IF(REGLAS!J5="OBSOLETO","","INSERT INTO INYCEXT.INYC_CONF_INF_REGLAS (COD_INFORME,TABLA,NOMBRE,REGLA,F_INICIO,F_FIN,DESCRIPCION) VALUES ("&REGLAS!B5&",'"&REGLAS!C5&"','"&REGLAS!D5&"','"&REGLAS!G5&"',TO_DATE('"&REGLAS!H5&"','yyyymmdd'),TO_DATE('"&REGLAS!I5&"','yyyymmdd'),'"&REGLAS!J5&"');") -> INSERT INTO INYCEXT.INYC_CONF_INF_REGLAS (COD_INFORME,TABLA,NOMBRE,REGLA,F_INICIO,F_FIN,DESCRIPCION) VALUES (1.1,'INYC_RPI_RESUMEN','SM - Objetivo Anual Total Ramos','SM-O-RPP-Inspector-ObjetivoAnual-NumPolizas-998',TO_DATE('20140101','yyyymmdd'),TO_DATE('22000101','yyyymmdd'),''); | B4: =IF(REGLAS!J5="OBSOLETO","","INSERT INTO INYCEXT.INYC_CONF_INF_REGLAS@tc_link (COD_INFORME,TABLA,NOMBRE,REGLA,F_INICIO,F_FIN,DESCRIPCION) VALUES ("&REGLAS!B5&",'"&REGLAS!C5&"','"&REGLAS!D5&"','"&REGLAS!G5&"',TO_DATE('"&REGLAS!H5&"','yyyymmdd'),TO_DATE('"&REGLAS!I5&"','yyyymmdd'),'"&REGLAS!J5&"');") -> INSERT INTO INYCEXT.INYC_CONF_INF_REGLAS@tc_link (COD_INFORME,TABLA,NOMBRE,REGLA,F_INICIO,F_FIN,DESCRIPCION) VALUES (1.1,'INYC_RPI_RESUMEN','SM - Objetivo Anual Total Ramos','SM-O-RPP-Inspector-ObjetivoAnual-NumPolizas-998',TO_DATE('20140101','yyyymmdd'),TO_DATE('22000101','yyyymmdd'),'');
A5: =IF(REGLAS!J6="OBSOLETO","","INSERT INTO INYCEXT.INYC_CONF_INF_REGLAS (COD_INFORME,TABLA,NOMBRE,REGLA,F_INICIO,F_FIN,DESCRIPCION) VALUES ("&REGLAS!B6&",'"&REGLAS!C6&"','"&REGLAS!D6&"','"&REGLAS!G6&"',TO_DATE('"&REGLAS!H6&"','yyyymmdd'),TO_DATE('"&REGLAS!I6&"','yyyymmdd'),'"&REGLAS!J6&"');") -> INSERT INTO INYCEXT.INYC_CONF_INF_REGLAS (COD_INFORME,TABLA,NOMBRE,REGLA,F_INICIO,F_FIN,DESCRIPCION) VALUES (1.1,'INYC_RPI_RESUMEN','SM - Objetivo Único Anual PC','SM-O-RPP-Inspector-ObjetivoUnicoAnual-PrimaCorregida',TO_DATE('20140101','yyyymmdd'),TO_DATE('22000101','yyyymmdd'),''); | B5: =IF(REGLAS!J6="OBSOLETO","","INSERT INTO INYCEXT.INYC_CONF_INF_REGLAS@tc_link (COD_INFORME,TABLA,NOMBRE,REGLA,F_INICIO,F_FIN,DESCRIPCION) VALUES ("&REGLAS!B6&",'"&REGLAS!C6&"','"&REGLAS!D6&"','"&REGLAS!G6&"',TO_DATE('"&REGLAS!H6&"','yyyymmdd'),TO_DATE('"&REGLAS!I6&"','yyyymmdd'),'"&REGLAS!J6&"');") -> INSERT INTO INYCEXT.INYC_CONF_INF_REGLAS@tc_link (COD_INFORME,TABLA,NOMBRE,REGLA,F_INICIO,F_FIN,DESCRIPCION) VALUES (1.1,'INYC_RPI_RESUMEN','SM - Objetivo Único Anual PC','SM-O-RPP-Inspector-ObjetivoUnicoAnual-PrimaCorregida',TO_DATE('20140101','yyyymmdd'),TO_DATE('22000101','yyyymmdd'),'');
A6: =IF(REGLAS!J7="OBSOLETO","","INSERT INTO INYCEXT.INYC_CONF_INF_REGLAS (COD_INFORME,TABLA,NOMBRE,REGLA,F_INICIO,F_FIN,DESCRIPCION) VALUES ("&REGLAS!B7&",'"&REGLAS!C7&"','"&REGLAS!D7&"','"&REGLAS!G7&"',TO_DATE('"&REGLAS!H7&"','yyyymmdd'),TO_DATE('"&REGLAS!I7&"','yyyymmdd'),'"&REGLAS!J7&"');") -> INSERT INTO INYCEXT.INYC_CONF_INF_REGLAS (COD_INFORME,TABLA,NOMBRE,REGLA,F_INICIO,F_FIN,DESCRIPCION) VALUES (1.1,'INYC_RPI_RESUMEN','SM - Objetivo Trimestral Rappel1 RRTT','SM-O-RPP-Inspector-ObjetivoTrimestral-Rappel1-NumPolizas-001',TO_DATE('20140101','yyyymmdd'),TO_DATE('22000101','yyyymmdd'),''); | B6: =IF(REGLAS!J7="OBSOLETO","","INSERT INTO INYCEXT.INYC_CONF_INF_REGLAS@tc_link (COD_INFORME,TABLA,NOMBRE,REGLA,F_INICIO,F_FIN,DESCRIPCION) VALUES ("&REGLAS!B7&",'"&REGLAS!C7&"','"&REGLAS!D7&"','"&REGLAS!G7&"',TO_DATE('"&REGLAS!H7&"','yyyymmdd'),TO_DATE('"&REGLAS!I7&"','yyyymmdd'),'"&REGLAS!J7&"');") -> INSERT INTO INYCEXT.INYC_CONF_INF_REGLAS@tc_link (COD_INFORME,TABLA,NOMBRE,REGLA,F_INICIO,F_FIN,DESCRIPCION) VALUES (1.1,'INYC_RPI_RESUMEN','SM - Objetivo Trimestral Rappel1 RRTT','SM-O-RPP-Inspector-ObjetivoTrimestral-Rappel1-NumPolizas-001',TO_DATE('20140101','yyyymmdd'),TO_DATE('22000101','yyyymmdd'),'');
A7: =IF(REGLAS!J8="OBSOLETO","","INSERT INTO INYCEXT.INYC_CONF_INF_REGLAS (COD_INFORME,TABLA,NOMBRE,REGLA,F_INICIO,F_FIN,DESCRIPCION) VALUES ("&REGLAS!B8&",'"&REGLAS!C8&"','"&REGLAS!D8&"','"&REGLAS!G8&"',TO_DATE('"&REGLAS!H8&"','yyyymmdd'),TO_DATE('"&REGLAS!I8&"','yyyymmdd'),'"&REGLAS!J8&"');") -> INSERT INTO INYCEXT.INYC_CONF_INF_REGLAS (COD_INFORME,TABLA,NOMBRE,REGLA,F_INICIO,F_FIN,DESCRIPCION) VALUES (1.1,'INYC_RPI_RESUMEN','SM - Objetivo Trimestral Rappel1 Hogar','SM-O-RPP-Inspector-ObjetivoTrimestral-Rappel1-NumPolizas-002',TO_DATE('20140101','yyyymmdd'),TO_DATE('22000101','yyyymmdd'),''); | B7: =IF(REGLAS!J8="OBSOLETO","","INSERT INTO INYCEXT.INYC_CONF_INF_REGLAS@tc_link (COD_INFORME,TABLA,NOMBRE,REGLA,F_INICIO,F_FIN,DESCRIPCION) VALUES ("&REGLAS!B8&",'"&REGLAS!C8&"','"&REGLAS!D8&"','"&REGLAS!G8&"',TO_DATE('"&REGLAS!H8&"','yyyymmdd'),TO_DATE('"&REGLAS!I8&"','yyyymmdd'),'"&REGLAS!J8&"');") -> INSERT INTO INYCEXT.INYC_CONF_INF_REGLAS@tc_link (COD_INFORME,TABLA,NOMBRE,REGLA,F_INICIO,F_FIN,DESCRIPCION) VALUES (1.1,'INYC_RPI_RESUMEN','SM - Objetivo Trimestral Rappel1 Hogar','SM-O-RPP-Inspector-ObjetivoTrimestral-Rappel1-NumPolizas-002',TO_DATE('20140101','yyyymmdd'),TO_DATE('22000101','yyyymmdd'),'');
